{"timestamp": "2025-05-08T12:22:17.362716+00:00", "level": "ERROR", "correlation_id": "9c3fd493-b4fe-4b1e-9d7f-768c62c57820", "error": "division by zero", "message": "Unhandled Exception", "logger": "error_logger"}
{"timestamp": "2025-05-08T12:22:42.824589+00:00", "level": "ERROR", "correlation_id": "454aead8-224f-4563-8f12-13ab1ea66fab", "error": "division by zero", "message": "Unhandled Exception", "logger": "error_logger"}
{"timestamp": "2025-05-08T12:22:43.203607+00:00", "level": "ERROR", "correlation_id": "d640ee73-28ab-4033-bfbb-647867125b57", "error": "division by zero", "message": "Unhandled Exception", "logger": "error_logger"}
{"timestamp": "2025-05-08T12:24:01.843499+00:00", "level": "ERROR", "correlation_id": "666d7b32-326f-4211-96ea-c5902573d374", "error": "division by zero", "message": "Unhandled Exception", "stack_trace": "  + Exception Group Traceback (most recent call last):\n  |   File \"c:\\users\\jamie\\pycharmprojects\\fastapitest\\venv\\lib\\site-packages\\starlette\\_utils.py\", line 76, in collapse_excgroups\n  |     yield\n  |   File \"c:\\users\\jamie\\pycharmprojects\\fastapitest\\venv\\lib\\site-packages\\starlette\\middleware\\base.py\", line 177, in __call__\n  |     async with anyio.create_task_group() as task_group:\n  |   File \"c:\\users\\jamie\\pycharmprojects\\fastapitest\\venv\\lib\\site-packages\\anyio\\_backends\\_asyncio.py\", line 772, in __aexit__\n  |     raise BaseExceptionGroup(\n  | exceptiongroup.ExceptionGroup: unhandled errors in a TaskGroup (1 sub-exception)\n  +-+---------------- 1 ----------------\n    | Traceback (most recent call last):\n    |   File \"c:\\users\\jamie\\pycharmprojects\\fastapitest\\venv\\lib\\site-packages\\starlette\\middleware\\errors.py\", line 165, in __call__\n    |     await self.app(scope, receive, _send)\n    |   File \"c:\\users\\jamie\\pycharmprojects\\fastapitest\\venv\\lib\\site-packages\\starlette\\middleware\\base.py\", line 176, in __call__\n    |     with recv_stream, send_stream, collapse_excgroups():\n    |   File \"C:\\Program Files\\Python310\\lib\\contextlib.py\", line 153, in __exit__\n    |     self.gen.throw(typ, value, traceback)\n    |   File \"c:\\users\\jamie\\pycharmprojects\\fastapitest\\venv\\lib\\site-packages\\starlette\\_utils.py\", line 82, in collapse_excgroups\n    |     raise exc\n    |   File \"c:\\users\\jamie\\pycharmprojects\\fastapitest\\venv\\lib\\site-packages\\starlette\\middleware\\base.py\", line 178, in __call__\n    |     response = await self.dispatch_func(request, call_next)\n    |   File \"C:\\Users\\Jamie\\PycharmProjects\\fastapitest\\main.py\", line 65, in dispatch\n    |     response = await call_next(request)\n    |   File \"c:\\users\\jamie\\pycharmprojects\\fastapitest\\venv\\lib\\site-packages\\starlette\\middleware\\base.py\", line 156, in call_next\n    |     raise app_exc\n    |   File \"c:\\users\\jamie\\pycharmprojects\\fastapitest\\venv\\lib\\site-packages\\starlette\\middleware\\base.py\", line 141, in coro\n    |     await self.app(scope, receive_or_disconnect, send_no_error)\n    |   File \"c:\\users\\jamie\\pycharmprojects\\fastapitest\\venv\\lib\\site-packages\\starlette\\middleware\\exceptions.py\", line 62, in __call__\n    |     await wrap_app_handling_exceptions(self.app, conn)(scope, receive, send)\n    |   File \"c:\\users\\jamie\\pycharmprojects\\fastapitest\\venv\\lib\\site-packages\\starlette\\_exception_handler.py\", line 53, in wrapped_app\n    |     raise exc\n    |   File \"c:\\users\\jamie\\pycharmprojects\\fastapitest\\venv\\lib\\site-packages\\starlette\\_exception_handler.py\", line 42, in wrapped_app\n    |     await app(scope, receive, sender)\n    |   File \"c:\\users\\jamie\\pycharmprojects\\fastapitest\\venv\\lib\\site-packages\\starlette\\routing.py\", line 714, in __call__\n    |     await self.middleware_stack(scope, receive, send)\n    |   File \"c:\\users\\jamie\\pycharmprojects\\fastapitest\\venv\\lib\\site-packages\\starlette\\routing.py\", line 734, in app\n    |     await route.handle(scope, receive, send)\n    |   File \"c:\\users\\jamie\\pycharmprojects\\fastapitest\\venv\\lib\\site-packages\\starlette\\routing.py\", line 288, in handle\n    |     await self.app(scope, receive, send)\n    |   File \"c:\\users\\jamie\\pycharmprojects\\fastapitest\\venv\\lib\\site-packages\\starlette\\routing.py\", line 76, in app\n    |     await wrap_app_handling_exceptions(app, request)(scope, receive, send)\n    |   File \"c:\\users\\jamie\\pycharmprojects\\fastapitest\\venv\\lib\\site-packages\\starlette\\_exception_handler.py\", line 53, in wrapped_app\n    |     raise exc\n    |   File \"c:\\users\\jamie\\pycharmprojects\\fastapitest\\venv\\lib\\site-packages\\starlette\\_exception_handler.py\", line 42, in wrapped_app\n    |     await app(scope, receive, sender)\n    |   File \"c:\\users\\jamie\\pycharmprojects\\fastapitest\\venv\\lib\\site-packages\\starlette\\routing.py\", line 73, in app\n    |     response = await f(request)\n    |   File \"c:\\users\\jamie\\pycharmprojects\\fastapitest\\venv\\lib\\site-packages\\fastapi\\routing.py\", line 301, in app\n    |     raw_response = await run_endpoint_function(\n    |   File \"c:\\users\\jamie\\pycharmprojects\\fastapitest\\venv\\lib\\site-packages\\fastapi\\routing.py\", line 212, in run_endpoint_function\n    |     return await dependant.call(**values)\n    |   File \"C:\\Users\\Jamie\\PycharmProjects\\fastapitest\\main.py\", line 116, in error\n    |     _ = 1 / 0  # Force an error to test logging\n    | ZeroDivisionError: division by zero\n    +------------------------------------\n\nDuring handling of the above exception, another exception occurred:\n\nTraceback (most recent call last):\n  File \"c:\\users\\jamie\\pycharmprojects\\fastapitest\\venv\\lib\\site-packages\\starlette\\middleware\\errors.py\", line 165, in __call__\n    await self.app(scope, receive, _send)\n  File \"c:\\users\\jamie\\pycharmprojects\\fastapitest\\venv\\lib\\site-packages\\starlette\\middleware\\base.py\", line 176, in __call__\n    with recv_stream, send_stream, collapse_excgroups():\n  File \"C:\\Program Files\\Python310\\lib\\contextlib.py\", line 153, in __exit__\n    self.gen.throw(typ, value, traceback)\n  File \"c:\\users\\jamie\\pycharmprojects\\fastapitest\\venv\\lib\\site-packages\\starlette\\_utils.py\", line 82, in collapse_excgroups\n    raise exc\n  File \"c:\\users\\jamie\\pycharmprojects\\fastapitest\\venv\\lib\\site-packages\\starlette\\middleware\\base.py\", line 178, in __call__\n    response = await self.dispatch_func(request, call_next)\n  File \"C:\\Users\\Jamie\\PycharmProjects\\fastapitest\\main.py\", line 65, in dispatch\n    response = await call_next(request)\n  File \"c:\\users\\jamie\\pycharmprojects\\fastapitest\\venv\\lib\\site-packages\\starlette\\middleware\\base.py\", line 156, in call_next\n    raise app_exc\n  File \"c:\\users\\jamie\\pycharmprojects\\fastapitest\\venv\\lib\\site-packages\\starlette\\middleware\\base.py\", line 141, in coro\n    await self.app(scope, receive_or_disconnect, send_no_error)\n  File \"c:\\users\\jamie\\pycharmprojects\\fastapitest\\venv\\lib\\site-packages\\starlette\\middleware\\exceptions.py\", line 62, in __call__\n    await wrap_app_handling_exceptions(self.app, conn)(scope, receive, send)\n  File \"c:\\users\\jamie\\pycharmprojects\\fastapitest\\venv\\lib\\site-packages\\starlette\\_exception_handler.py\", line 53, in wrapped_app\n    raise exc\n  File \"c:\\users\\jamie\\pycharmprojects\\fastapitest\\venv\\lib\\site-packages\\starlette\\_exception_handler.py\", line 42, in wrapped_app\n    await app(scope, receive, sender)\n  File \"c:\\users\\jamie\\pycharmprojects\\fastapitest\\venv\\lib\\site-packages\\starlette\\routing.py\", line 714, in __call__\n    await self.middleware_stack(scope, receive, send)\n  File \"c:\\users\\jamie\\pycharmprojects\\fastapitest\\venv\\lib\\site-packages\\starlette\\routing.py\", line 734, in app\n    await route.handle(scope, receive, send)\n  File \"c:\\users\\jamie\\pycharmprojects\\fastapitest\\venv\\lib\\site-packages\\starlette\\routing.py\", line 288, in handle\n    await self.app(scope, receive, send)\n  File \"c:\\users\\jamie\\pycharmprojects\\fastapitest\\venv\\lib\\site-packages\\starlette\\routing.py\", line 76, in app\n    await wrap_app_handling_exceptions(app, request)(scope, receive, send)\n  File \"c:\\users\\jamie\\pycharmprojects\\fastapitest\\venv\\lib\\site-packages\\starlette\\_exception_handler.py\", line 53, in wrapped_app\n    raise exc\n  File \"c:\\users\\jamie\\pycharmprojects\\fastapitest\\venv\\lib\\site-packages\\starlette\\_exception_handler.py\", line 42, in wrapped_app\n    await app(scope, receive, sender)\n  File \"c:\\users\\jamie\\pycharmprojects\\fastapitest\\venv\\lib\\site-packages\\starlette\\routing.py\", line 73, in app\n    response = await f(request)\n  File \"c:\\users\\jamie\\pycharmprojects\\fastapitest\\venv\\lib\\site-packages\\fastapi\\routing.py\", line 301, in app\n    raw_response = await run_endpoint_function(\n  File \"c:\\users\\jamie\\pycharmprojects\\fastapitest\\venv\\lib\\site-packages\\fastapi\\routing.py\", line 212, in run_endpoint_function\n    return await dependant.call(**values)\n  File \"C:\\Users\\Jamie\\PycharmProjects\\fastapitest\\main.py\", line 116, in error\n    _ = 1 / 0  # Force an error to test logging\nZeroDivisionError: division by zero\n", "logger": "error_logger"}
{"timestamp": "2025-05-08T12:24:55.153156+00:00", "level": "ERROR", "correlation_id": "11b06ab4-dcf0-4b04-a34e-483e0f2fbd2d", "error": "division by zero", "message": "Unhandled Exception", "stack_trace": "  + Exception Group Traceback (most recent call last):\n  |   File \"c:\\users\\jamie\\pycharmprojects\\fastapitest\\venv\\lib\\site-packages\\starlette\\_utils.py\", line 76, in collapse_excgroups\n  |     yield\n  |   File \"c:\\users\\jamie\\pycharmprojects\\fastapitest\\venv\\lib\\site-packages\\starlette\\middleware\\base.py\", line 177, in __call__\n  |     async with anyio.create_task_group() as task_group:\n  |   File \"c:\\users\\jamie\\pycharmprojects\\fastapitest\\venv\\lib\\site-packages\\anyio\\_backends\\_asyncio.py\", line 772, in __aexit__\n  |     raise BaseExceptionGroup(\n  | exceptiongroup.ExceptionGroup: unhandled errors in a TaskGroup (1 sub-exception)\n  +-+---------------- 1 ----------------\n    | Traceback (most recent call last):\n    |   File \"c:\\users\\jamie\\pycharmprojects\\fastapitest\\venv\\lib\\site-packages\\starlette\\middleware\\errors.py\", line 165, in __call__\n    |     await self.app(scope, receive, _send)\n    |   File \"c:\\users\\jamie\\pycharmprojects\\fastapitest\\venv\\lib\\site-packages\\starlette\\middleware\\base.py\", line 176, in __call__\n    |     with recv_stream, send_stream, collapse_excgroups():\n    |   File \"C:\\Program Files\\Python310\\lib\\contextlib.py\", line 153, in __exit__\n    |     self.gen.throw(typ, value, traceback)\n    |   File \"c:\\users\\jamie\\pycharmprojects\\fastapitest\\venv\\lib\\site-packages\\starlette\\_utils.py\", line 82, in collapse_excgroups\n    |     raise exc\n    |   File \"c:\\users\\jamie\\pycharmprojects\\fastapitest\\venv\\lib\\site-packages\\starlette\\middleware\\base.py\", line 178, in __call__\n    |     response = await self.dispatch_func(request, call_next)\n    |   File \"C:\\Users\\Jamie\\PycharmProjects\\fastapitest\\main.py\", line 65, in dispatch\n    |     response = await call_next(request)\n    |   File \"c:\\users\\jamie\\pycharmprojects\\fastapitest\\venv\\lib\\site-packages\\starlette\\middleware\\base.py\", line 156, in call_next\n    |     raise app_exc\n    |   File \"c:\\users\\jamie\\pycharmprojects\\fastapitest\\venv\\lib\\site-packages\\starlette\\middleware\\base.py\", line 141, in coro\n    |     await self.app(scope, receive_or_disconnect, send_no_error)\n    |   File \"c:\\users\\jamie\\pycharmprojects\\fastapitest\\venv\\lib\\site-packages\\starlette\\middleware\\exceptions.py\", line 62, in __call__\n    |     await wrap_app_handling_exceptions(self.app, conn)(scope, receive, send)\n    |   File \"c:\\users\\jamie\\pycharmprojects\\fastapitest\\venv\\lib\\site-packages\\starlette\\_exception_handler.py\", line 53, in wrapped_app\n    |     raise exc\n    |   File \"c:\\users\\jamie\\pycharmprojects\\fastapitest\\venv\\lib\\site-packages\\starlette\\_exception_handler.py\", line 42, in wrapped_app\n    |     await app(scope, receive, sender)\n    |   File \"c:\\users\\jamie\\pycharmprojects\\fastapitest\\venv\\lib\\site-packages\\starlette\\routing.py\", line 714, in __call__\n    |     await self.middleware_stack(scope, receive, send)\n    |   File \"c:\\users\\jamie\\pycharmprojects\\fastapitest\\venv\\lib\\site-packages\\starlette\\routing.py\", line 734, in app\n    |     await route.handle(scope, receive, send)\n    |   File \"c:\\users\\jamie\\pycharmprojects\\fastapitest\\venv\\lib\\site-packages\\starlette\\routing.py\", line 288, in handle\n    |     await self.app(scope, receive, send)\n    |   File \"c:\\users\\jamie\\pycharmprojects\\fastapitest\\venv\\lib\\site-packages\\starlette\\routing.py\", line 76, in app\n    |     await wrap_app_handling_exceptions(app, request)(scope, receive, send)\n    |   File \"c:\\users\\jamie\\pycharmprojects\\fastapitest\\venv\\lib\\site-packages\\starlette\\_exception_handler.py\", line 53, in wrapped_app\n    |     raise exc\n    |   File \"c:\\users\\jamie\\pycharmprojects\\fastapitest\\venv\\lib\\site-packages\\starlette\\_exception_handler.py\", line 42, in wrapped_app\n    |     await app(scope, receive, sender)\n    |   File \"c:\\users\\jamie\\pycharmprojects\\fastapitest\\venv\\lib\\site-packages\\starlette\\routing.py\", line 73, in app\n    |     response = await f(request)\n    |   File \"c:\\users\\jamie\\pycharmprojects\\fastapitest\\venv\\lib\\site-packages\\fastapi\\routing.py\", line 301, in app\n    |     raw_response = await run_endpoint_function(\n    |   File \"c:\\users\\jamie\\pycharmprojects\\fastapitest\\venv\\lib\\site-packages\\fastapi\\routing.py\", line 212, in run_endpoint_function\n    |     return await dependant.call(**values)\n    |   File \"C:\\Users\\Jamie\\PycharmProjects\\fastapitest\\main.py\", line 116, in error\n    |     _ = 1 / 0  # Force an error to test logging\n    | ZeroDivisionError: division by zero\n    +------------------------------------\n\nDuring handling of the above exception, another exception occurred:\n\nTraceback (most recent call last):\n  File \"c:\\users\\jamie\\pycharmprojects\\fastapitest\\venv\\lib\\site-packages\\starlette\\middleware\\errors.py\", line 165, in __call__\n    await self.app(scope, receive, _send)\n  File \"c:\\users\\jamie\\pycharmprojects\\fastapitest\\venv\\lib\\site-packages\\starlette\\middleware\\base.py\", line 176, in __call__\n    with recv_stream, send_stream, collapse_excgroups():\n  File \"C:\\Program Files\\Python310\\lib\\contextlib.py\", line 153, in __exit__\n    self.gen.throw(typ, value, traceback)\n  File \"c:\\users\\jamie\\pycharmprojects\\fastapitest\\venv\\lib\\site-packages\\starlette\\_utils.py\", line 82, in collapse_excgroups\n    raise exc\n  File \"c:\\users\\jamie\\pycharmprojects\\fastapitest\\venv\\lib\\site-packages\\starlette\\middleware\\base.py\", line 178, in __call__\n    response = await self.dispatch_func(request, call_next)\n  File \"C:\\Users\\Jamie\\PycharmProjects\\fastapitest\\main.py\", line 65, in dispatch\n    response = await call_next(request)\n  File \"c:\\users\\jamie\\pycharmprojects\\fastapitest\\venv\\lib\\site-packages\\starlette\\middleware\\base.py\", line 156, in call_next\n    raise app_exc\n  File \"c:\\users\\jamie\\pycharmprojects\\fastapitest\\venv\\lib\\site-packages\\starlette\\middleware\\base.py\", line 141, in coro\n    await self.app(scope, receive_or_disconnect, send_no_error)\n  File \"c:\\users\\jamie\\pycharmprojects\\fastapitest\\venv\\lib\\site-packages\\starlette\\middleware\\exceptions.py\", line 62, in __call__\n    await wrap_app_handling_exceptions(self.app, conn)(scope, receive, send)\n  File \"c:\\users\\jamie\\pycharmprojects\\fastapitest\\venv\\lib\\site-packages\\starlette\\_exception_handler.py\", line 53, in wrapped_app\n    raise exc\n  File \"c:\\users\\jamie\\pycharmprojects\\fastapitest\\venv\\lib\\site-packages\\starlette\\_exception_handler.py\", line 42, in wrapped_app\n    await app(scope, receive, sender)\n  File \"c:\\users\\jamie\\pycharmprojects\\fastapitest\\venv\\lib\\site-packages\\starlette\\routing.py\", line 714, in __call__\n    await self.middleware_stack(scope, receive, send)\n  File \"c:\\users\\jamie\\pycharmprojects\\fastapitest\\venv\\lib\\site-packages\\starlette\\routing.py\", line 734, in app\n    await route.handle(scope, receive, send)\n  File \"c:\\users\\jamie\\pycharmprojects\\fastapitest\\venv\\lib\\site-packages\\starlette\\routing.py\", line 288, in handle\n    await self.app(scope, receive, send)\n  File \"c:\\users\\jamie\\pycharmprojects\\fastapitest\\venv\\lib\\site-packages\\starlette\\routing.py\", line 76, in app\n    await wrap_app_handling_exceptions(app, request)(scope, receive, send)\n  File \"c:\\users\\jamie\\pycharmprojects\\fastapitest\\venv\\lib\\site-packages\\starlette\\_exception_handler.py\", line 53, in wrapped_app\n    raise exc\n  File \"c:\\users\\jamie\\pycharmprojects\\fastapitest\\venv\\lib\\site-packages\\starlette\\_exception_handler.py\", line 42, in wrapped_app\n    await app(scope, receive, sender)\n  File \"c:\\users\\jamie\\pycharmprojects\\fastapitest\\venv\\lib\\site-packages\\starlette\\routing.py\", line 73, in app\n    response = await f(request)\n  File \"c:\\users\\jamie\\pycharmprojects\\fastapitest\\venv\\lib\\site-packages\\fastapi\\routing.py\", line 301, in app\n    raw_response = await run_endpoint_function(\n  File \"c:\\users\\jamie\\pycharmprojects\\fastapitest\\venv\\lib\\site-packages\\fastapi\\routing.py\", line 212, in run_endpoint_function\n    return await dependant.call(**values)\n  File \"C:\\Users\\Jamie\\PycharmProjects\\fastapitest\\main.py\", line 116, in error\n    _ = 1 / 0  # Force an error to test logging\nZeroDivisionError: division by zero\n", "exc_info": "  + Exception Group Traceback (most recent call last):\n  |   File \"c:\\users\\jamie\\pycharmprojects\\fastapitest\\venv\\lib\\site-packages\\starlette\\_utils.py\", line 76, in collapse_excgroups\n  |     yield\n  |   File \"c:\\users\\jamie\\pycharmprojects\\fastapitest\\venv\\lib\\site-packages\\starlette\\middleware\\base.py\", line 177, in __call__\n  |     async with anyio.create_task_group() as task_group:\n  |   File \"c:\\users\\jamie\\pycharmprojects\\fastapitest\\venv\\lib\\site-packages\\anyio\\_backends\\_asyncio.py\", line 772, in __aexit__\n  |     raise BaseExceptionGroup(\n  | exceptiongroup.ExceptionGroup: unhandled errors in a TaskGroup (1 sub-exception)\n  +-+---------------- 1 ----------------\n    | Traceback (most recent call last):\n    |   File \"c:\\users\\jamie\\pycharmprojects\\fastapitest\\venv\\lib\\site-packages\\starlette\\middleware\\errors.py\", line 165, in __call__\n    |     await self.app(scope, receive, _send)\n    |   File \"c:\\users\\jamie\\pycharmprojects\\fastapitest\\venv\\lib\\site-packages\\starlette\\middleware\\base.py\", line 176, in __call__\n    |     with recv_stream, send_stream, collapse_excgroups():\n    |   File \"C:\\Program Files\\Python310\\lib\\contextlib.py\", line 153, in __exit__\n    |     self.gen.throw(typ, value, traceback)\n    |   File \"c:\\users\\jamie\\pycharmprojects\\fastapitest\\venv\\lib\\site-packages\\starlette\\_utils.py\", line 82, in collapse_excgroups\n    |     raise exc\n    |   File \"c:\\users\\jamie\\pycharmprojects\\fastapitest\\venv\\lib\\site-packages\\starlette\\middleware\\base.py\", line 178, in __call__\n    |     response = await self.dispatch_func(request, call_next)\n    |   File \"C:\\Users\\Jamie\\PycharmProjects\\fastapitest\\main.py\", line 65, in dispatch\n    |     response = await call_next(request)\n    |   File \"c:\\users\\jamie\\pycharmprojects\\fastapitest\\venv\\lib\\site-packages\\starlette\\middleware\\base.py\", line 156, in call_next\n    |     raise app_exc\n    |   File \"c:\\users\\jamie\\pycharmprojects\\fastapitest\\venv\\lib\\site-packages\\starlette\\middleware\\base.py\", line 141, in coro\n    |     await self.app(scope, receive_or_disconnect, send_no_error)\n    |   File \"c:\\users\\jamie\\pycharmprojects\\fastapitest\\venv\\lib\\site-packages\\starlette\\middleware\\exceptions.py\", line 62, in __call__\n    |     await wrap_app_handling_exceptions(self.app, conn)(scope, receive, send)\n    |   File \"c:\\users\\jamie\\pycharmprojects\\fastapitest\\venv\\lib\\site-packages\\starlette\\_exception_handler.py\", line 53, in wrapped_app\n    |     raise exc\n    |   File \"c:\\users\\jamie\\pycharmprojects\\fastapitest\\venv\\lib\\site-packages\\starlette\\_exception_handler.py\", line 42, in wrapped_app\n    |     await app(scope, receive, sender)\n    |   File \"c:\\users\\jamie\\pycharmprojects\\fastapitest\\venv\\lib\\site-packages\\starlette\\routing.py\", line 714, in __call__\n    |     await self.middleware_stack(scope, receive, send)\n    |   File \"c:\\users\\jamie\\pycharmprojects\\fastapitest\\venv\\lib\\site-packages\\starlette\\routing.py\", line 734, in app\n    |     await route.handle(scope, receive, send)\n    |   File \"c:\\users\\jamie\\pycharmprojects\\fastapitest\\venv\\lib\\site-packages\\starlette\\routing.py\", line 288, in handle\n    |     await self.app(scope, receive, send)\n    |   File \"c:\\users\\jamie\\pycharmprojects\\fastapitest\\venv\\lib\\site-packages\\starlette\\routing.py\", line 76, in app\n    |     await wrap_app_handling_exceptions(app, request)(scope, receive, send)\n    |   File \"c:\\users\\jamie\\pycharmprojects\\fastapitest\\venv\\lib\\site-packages\\starlette\\_exception_handler.py\", line 53, in wrapped_app\n    |     raise exc\n    |   File \"c:\\users\\jamie\\pycharmprojects\\fastapitest\\venv\\lib\\site-packages\\starlette\\_exception_handler.py\", line 42, in wrapped_app\n    |     await app(scope, receive, sender)\n    |   File \"c:\\users\\jamie\\pycharmprojects\\fastapitest\\venv\\lib\\site-packages\\starlette\\routing.py\", line 73, in app\n    |     response = await f(request)\n    |   File \"c:\\users\\jamie\\pycharmprojects\\fastapitest\\venv\\lib\\site-packages\\fastapi\\routing.py\", line 301, in app\n    |     raw_response = await run_endpoint_function(\n    |   File \"c:\\users\\jamie\\pycharmprojects\\fastapitest\\venv\\lib\\site-packages\\fastapi\\routing.py\", line 212, in run_endpoint_function\n    |     return await dependant.call(**values)\n    |   File \"C:\\Users\\Jamie\\PycharmProjects\\fastapitest\\main.py\", line 116, in error\n    |     _ = 1 / 0  # Force an error to test logging\n    | ZeroDivisionError: division by zero\n    +------------------------------------\n\nDuring handling of the above exception, another exception occurred:\n\nTraceback (most recent call last):\n  File \"c:\\users\\jamie\\pycharmprojects\\fastapitest\\venv\\lib\\site-packages\\starlette\\middleware\\errors.py\", line 165, in __call__\n    await self.app(scope, receive, _send)\n  File \"c:\\users\\jamie\\pycharmprojects\\fastapitest\\venv\\lib\\site-packages\\starlette\\middleware\\base.py\", line 176, in __call__\n    with recv_stream, send_stream, collapse_excgroups():\n  File \"C:\\Program Files\\Python310\\lib\\contextlib.py\", line 153, in __exit__\n    self.gen.throw(typ, value, traceback)\n  File \"c:\\users\\jamie\\pycharmprojects\\fastapitest\\venv\\lib\\site-packages\\starlette\\_utils.py\", line 82, in collapse_excgroups\n    raise exc\n  File \"c:\\users\\jamie\\pycharmprojects\\fastapitest\\venv\\lib\\site-packages\\starlette\\middleware\\base.py\", line 178, in __call__\n    response = await self.dispatch_func(request, call_next)\n  File \"C:\\Users\\Jamie\\PycharmProjects\\fastapitest\\main.py\", line 65, in dispatch\n    response = await call_next(request)\n  File \"c:\\users\\jamie\\pycharmprojects\\fastapitest\\venv\\lib\\site-packages\\starlette\\middleware\\base.py\", line 156, in call_next\n    raise app_exc\n  File \"c:\\users\\jamie\\pycharmprojects\\fastapitest\\venv\\lib\\site-packages\\starlette\\middleware\\base.py\", line 141, in coro\n    await self.app(scope, receive_or_disconnect, send_no_error)\n  File \"c:\\users\\jamie\\pycharmprojects\\fastapitest\\venv\\lib\\site-packages\\starlette\\middleware\\exceptions.py\", line 62, in __call__\n    await wrap_app_handling_exceptions(self.app, conn)(scope, receive, send)\n  File \"c:\\users\\jamie\\pycharmprojects\\fastapitest\\venv\\lib\\site-packages\\starlette\\_exception_handler.py\", line 53, in wrapped_app\n    raise exc\n  File \"c:\\users\\jamie\\pycharmprojects\\fastapitest\\venv\\lib\\site-packages\\starlette\\_exception_handler.py\", line 42, in wrapped_app\n    await app(scope, receive, sender)\n  File \"c:\\users\\jamie\\pycharmprojects\\fastapitest\\venv\\lib\\site-packages\\starlette\\routing.py\", line 714, in __call__\n    await self.middleware_stack(scope, receive, send)\n  File \"c:\\users\\jamie\\pycharmprojects\\fastapitest\\venv\\lib\\site-packages\\starlette\\routing.py\", line 734, in app\n    await route.handle(scope, receive, send)\n  File \"c:\\users\\jamie\\pycharmprojects\\fastapitest\\venv\\lib\\site-packages\\starlette\\routing.py\", line 288, in handle\n    await self.app(scope, receive, send)\n  File \"c:\\users\\jamie\\pycharmprojects\\fastapitest\\venv\\lib\\site-packages\\starlette\\routing.py\", line 76, in app\n    await wrap_app_handling_exceptions(app, request)(scope, receive, send)\n  File \"c:\\users\\jamie\\pycharmprojects\\fastapitest\\venv\\lib\\site-packages\\starlette\\_exception_handler.py\", line 53, in wrapped_app\n    raise exc\n  File \"c:\\users\\jamie\\pycharmprojects\\fastapitest\\venv\\lib\\site-packages\\starlette\\_exception_handler.py\", line 42, in wrapped_app\n    await app(scope, receive, sender)\n  File \"c:\\users\\jamie\\pycharmprojects\\fastapitest\\venv\\lib\\site-packages\\starlette\\routing.py\", line 73, in app\n    response = await f(request)\n  File \"c:\\users\\jamie\\pycharmprojects\\fastapitest\\venv\\lib\\site-packages\\fastapi\\routing.py\", line 301, in app\n    raw_response = await run_endpoint_function(\n  File \"c:\\users\\jamie\\pycharmprojects\\fastapitest\\venv\\lib\\site-packages\\fastapi\\routing.py\", line 212, in run_endpoint_function\n    return await dependant.call(**values)\n  File \"C:\\Users\\Jamie\\PycharmProjects\\fastapitest\\main.py\", line 116, in error\n    _ = 1 / 0  # Force an error to test logging\nZeroDivisionError: division by zero", "logger": "error_logger"}
{"timestamp": "2025-05-08T12:26:44.435042+00:00", "level": "ERROR", "correlation_id": "3f495d5a-5739-4e16-80d5-ffaf1bab0b00", "error": "division by zero", "message": "Unhandled Exception", "stack_trace": "  + Exception Group Traceback (most recent call last):\n  |   File \"c:\\users\\jamie\\pycharmprojects\\fastapitest\\venv\\lib\\site-packages\\starlette\\_utils.py\", line 76, in collapse_excgroups\n  |     yield\n  |   File \"c:\\users\\jamie\\pycharmprojects\\fastapitest\\venv\\lib\\site-packages\\starlette\\middleware\\base.py\", line 177, in __call__\n  |     async with anyio.create_task_group() as task_group:\n  |   File \"c:\\users\\jamie\\pycharmprojects\\fastapitest\\venv\\lib\\site-packages\\anyio\\_backends\\_asyncio.py\", line 772, in __aexit__\n  |     raise BaseExceptionGroup(\n  | exceptiongroup.ExceptionGroup: unhandled errors in a TaskGroup (1 sub-exception)\n  +-+---------------- 1 ----------------\n    | Traceback (most recent call last):\n    |   File \"c:\\users\\jamie\\pycharmprojects\\fastapitest\\venv\\lib\\site-packages\\starlette\\middleware\\errors.py\", line 165, in __call__\n    |     await self.app(scope, receive, _send)\n    |   File \"c:\\users\\jamie\\pycharmprojects\\fastapitest\\venv\\lib\\site-packages\\starlette\\middleware\\base.py\", line 176, in __call__\n    |     with recv_stream, send_stream, collapse_excgroups():\n    |   File \"C:\\Program Files\\Python310\\lib\\contextlib.py\", line 153, in __exit__\n    |     self.gen.throw(typ, value, traceback)\n    |   File \"c:\\users\\jamie\\pycharmprojects\\fastapitest\\venv\\lib\\site-packages\\starlette\\_utils.py\", line 82, in collapse_excgroups\n    |     raise exc\n    |   File \"c:\\users\\jamie\\pycharmprojects\\fastapitest\\venv\\lib\\site-packages\\starlette\\middleware\\base.py\", line 178, in __call__\n    |     response = await self.dispatch_func(request, call_next)\n    |   File \"C:\\Users\\Jamie\\PycharmProjects\\fastapitest\\main.py\", line 68, in dispatch\n    |     response = await call_next(request)\n    |   File \"c:\\users\\jamie\\pycharmprojects\\fastapitest\\venv\\lib\\site-packages\\starlette\\middleware\\base.py\", line 156, in call_next\n    |     raise app_exc\n    |   File \"c:\\users\\jamie\\pycharmprojects\\fastapitest\\venv\\lib\\site-packages\\starlette\\middleware\\base.py\", line 141, in coro\n    |     await self.app(scope, receive_or_disconnect, send_no_error)\n    |   File \"c:\\users\\jamie\\pycharmprojects\\fastapitest\\venv\\lib\\site-packages\\starlette\\middleware\\exceptions.py\", line 62, in __call__\n    |     await wrap_app_handling_exceptions(self.app, conn)(scope, receive, send)\n    |   File \"c:\\users\\jamie\\pycharmprojects\\fastapitest\\venv\\lib\\site-packages\\starlette\\_exception_handler.py\", line 53, in wrapped_app\n    |     raise exc\n    |   File \"c:\\users\\jamie\\pycharmprojects\\fastapitest\\venv\\lib\\site-packages\\starlette\\_exception_handler.py\", line 42, in wrapped_app\n    |     await app(scope, receive, sender)\n    |   File \"c:\\users\\jamie\\pycharmprojects\\fastapitest\\venv\\lib\\site-packages\\starlette\\routing.py\", line 714, in __call__\n    |     await self.middleware_stack(scope, receive, send)\n    |   File \"c:\\users\\jamie\\pycharmprojects\\fastapitest\\venv\\lib\\site-packages\\starlette\\routing.py\", line 734, in app\n    |     await route.handle(scope, receive, send)\n    |   File \"c:\\users\\jamie\\pycharmprojects\\fastapitest\\venv\\lib\\site-packages\\starlette\\routing.py\", line 288, in handle\n    |     await self.app(scope, receive, send)\n    |   File \"c:\\users\\jamie\\pycharmprojects\\fastapitest\\venv\\lib\\site-packages\\starlette\\routing.py\", line 76, in app\n    |     await wrap_app_handling_exceptions(app, request)(scope, receive, send)\n    |   File \"c:\\users\\jamie\\pycharmprojects\\fastapitest\\venv\\lib\\site-packages\\starlette\\_exception_handler.py\", line 53, in wrapped_app\n    |     raise exc\n    |   File \"c:\\users\\jamie\\pycharmprojects\\fastapitest\\venv\\lib\\site-packages\\starlette\\_exception_handler.py\", line 42, in wrapped_app\n    |     await app(scope, receive, sender)\n    |   File \"c:\\users\\jamie\\pycharmprojects\\fastapitest\\venv\\lib\\site-packages\\starlette\\routing.py\", line 73, in app\n    |     response = await f(request)\n    |   File \"c:\\users\\jamie\\pycharmprojects\\fastapitest\\venv\\lib\\site-packages\\fastapi\\routing.py\", line 301, in app\n    |     raw_response = await run_endpoint_function(\n    |   File \"c:\\users\\jamie\\pycharmprojects\\fastapitest\\venv\\lib\\site-packages\\fastapi\\routing.py\", line 212, in run_endpoint_function\n    |     return await dependant.call(**values)\n    |   File \"C:\\Users\\Jamie\\PycharmProjects\\fastapitest\\main.py\", line 122, in error\n    |     _ = 1 / 0  # Force an error to test logging\n    | ZeroDivisionError: division by zero\n    +------------------------------------\n\nDuring handling of the above exception, another exception occurred:\n\nTraceback (most recent call last):\n  File \"c:\\users\\jamie\\pycharmprojects\\fastapitest\\venv\\lib\\site-packages\\starlette\\middleware\\errors.py\", line 165, in __call__\n    await self.app(scope, receive, _send)\n  File \"c:\\users\\jamie\\pycharmprojects\\fastapitest\\venv\\lib\\site-packages\\starlette\\middleware\\base.py\", line 176, in __call__\n    with recv_stream, send_stream, collapse_excgroups():\n  File \"C:\\Program Files\\Python310\\lib\\contextlib.py\", line 153, in __exit__\n    self.gen.throw(typ, value, traceback)\n  File \"c:\\users\\jamie\\pycharmprojects\\fastapitest\\venv\\lib\\site-packages\\starlette\\_utils.py\", line 82, in collapse_excgroups\n    raise exc\n  File \"c:\\users\\jamie\\pycharmprojects\\fastapitest\\venv\\lib\\site-packages\\starlette\\middleware\\base.py\", line 178, in __call__\n    response = await self.dispatch_func(request, call_next)\n  File \"C:\\Users\\Jamie\\PycharmProjects\\fastapitest\\main.py\", line 68, in dispatch\n    response = await call_next(request)\n  File \"c:\\users\\jamie\\pycharmprojects\\fastapitest\\venv\\lib\\site-packages\\starlette\\middleware\\base.py\", line 156, in call_next\n    raise app_exc\n  File \"c:\\users\\jamie\\pycharmprojects\\fastapitest\\venv\\lib\\site-packages\\starlette\\middleware\\base.py\", line 141, in coro\n    await self.app(scope, receive_or_disconnect, send_no_error)\n  File \"c:\\users\\jamie\\pycharmprojects\\fastapitest\\venv\\lib\\site-packages\\starlette\\middleware\\exceptions.py\", line 62, in __call__\n    await wrap_app_handling_exceptions(self.app, conn)(scope, receive, send)\n  File \"c:\\users\\jamie\\pycharmprojects\\fastapitest\\venv\\lib\\site-packages\\starlette\\_exception_handler.py\", line 53, in wrapped_app\n    raise exc\n  File \"c:\\users\\jamie\\pycharmprojects\\fastapitest\\venv\\lib\\site-packages\\starlette\\_exception_handler.py\", line 42, in wrapped_app\n    await app(scope, receive, sender)\n  File \"c:\\users\\jamie\\pycharmprojects\\fastapitest\\venv\\lib\\site-packages\\starlette\\routing.py\", line 714, in __call__\n    await self.middleware_stack(scope, receive, send)\n  File \"c:\\users\\jamie\\pycharmprojects\\fastapitest\\venv\\lib\\site-packages\\starlette\\routing.py\", line 734, in app\n    await route.handle(scope, receive, send)\n  File \"c:\\users\\jamie\\pycharmprojects\\fastapitest\\venv\\lib\\site-packages\\starlette\\routing.py\", line 288, in handle\n    await self.app(scope, receive, send)\n  File \"c:\\users\\jamie\\pycharmprojects\\fastapitest\\venv\\lib\\site-packages\\starlette\\routing.py\", line 76, in app\n    await wrap_app_handling_exceptions(app, request)(scope, receive, send)\n  File \"c:\\users\\jamie\\pycharmprojects\\fastapitest\\venv\\lib\\site-packages\\starlette\\_exception_handler.py\", line 53, in wrapped_app\n    raise exc\n  File \"c:\\users\\jamie\\pycharmprojects\\fastapitest\\venv\\lib\\site-packages\\starlette\\_exception_handler.py\", line 42, in wrapped_app\n    await app(scope, receive, sender)\n  File \"c:\\users\\jamie\\pycharmprojects\\fastapitest\\venv\\lib\\site-packages\\starlette\\routing.py\", line 73, in app\n    response = await f(request)\n  File \"c:\\users\\jamie\\pycharmprojects\\fastapitest\\venv\\lib\\site-packages\\fastapi\\routing.py\", line 301, in app\n    raw_response = await run_endpoint_function(\n  File \"c:\\users\\jamie\\pycharmprojects\\fastapitest\\venv\\lib\\site-packages\\fastapi\\routing.py\", line 212, in run_endpoint_function\n    return await dependant.call(**values)\n  File \"C:\\Users\\Jamie\\PycharmProjects\\fastapitest\\main.py\", line 122, in error\n    _ = 1 / 0  # Force an error to test logging\nZeroDivisionError: division by zero\n", "logger": "error_logger"}
{"timestamp": "2025-05-08T12:26:44.655048+00:00", "level": "ERROR", "correlation_id": "97fbb4cf-cb45-47a4-b2d8-49fbd76fab0d", "error": "division by zero", "message": "Unhandled Exception", "stack_trace": "  + Exception Group Traceback (most recent call last):\n  |   File \"c:\\users\\jamie\\pycharmprojects\\fastapitest\\venv\\lib\\site-packages\\starlette\\_utils.py\", line 76, in collapse_excgroups\n  |     yield\n  |   File \"c:\\users\\jamie\\pycharmprojects\\fastapitest\\venv\\lib\\site-packages\\starlette\\middleware\\base.py\", line 177, in __call__\n  |     async with anyio.create_task_group() as task_group:\n  |   File \"c:\\users\\jamie\\pycharmprojects\\fastapitest\\venv\\lib\\site-packages\\anyio\\_backends\\_asyncio.py\", line 772, in __aexit__\n  |     raise BaseExceptionGroup(\n  | exceptiongroup.ExceptionGroup: unhandled errors in a TaskGroup (1 sub-exception)\n  +-+---------------- 1 ----------------\n    | Traceback (most recent call last):\n    |   File \"c:\\users\\jamie\\pycharmprojects\\fastapitest\\venv\\lib\\site-packages\\starlette\\middleware\\errors.py\", line 165, in __call__\n    |     await self.app(scope, receive, _send)\n    |   File \"c:\\users\\jamie\\pycharmprojects\\fastapitest\\venv\\lib\\site-packages\\starlette\\middleware\\base.py\", line 176, in __call__\n    |     with recv_stream, send_stream, collapse_excgroups():\n    |   File \"C:\\Program Files\\Python310\\lib\\contextlib.py\", line 153, in __exit__\n    |     self.gen.throw(typ, value, traceback)\n    |   File \"c:\\users\\jamie\\pycharmprojects\\fastapitest\\venv\\lib\\site-packages\\starlette\\_utils.py\", line 82, in collapse_excgroups\n    |     raise exc\n    |   File \"c:\\users\\jamie\\pycharmprojects\\fastapitest\\venv\\lib\\site-packages\\starlette\\middleware\\base.py\", line 178, in __call__\n    |     response = await self.dispatch_func(request, call_next)\n    |   File \"C:\\Users\\Jamie\\PycharmProjects\\fastapitest\\main.py\", line 68, in dispatch\n    |     response = await call_next(request)\n    |   File \"c:\\users\\jamie\\pycharmprojects\\fastapitest\\venv\\lib\\site-packages\\starlette\\middleware\\base.py\", line 156, in call_next\n    |     raise app_exc\n    |   File \"c:\\users\\jamie\\pycharmprojects\\fastapitest\\venv\\lib\\site-packages\\starlette\\middleware\\base.py\", line 141, in coro\n    |     await self.app(scope, receive_or_disconnect, send_no_error)\n    |   File \"c:\\users\\jamie\\pycharmprojects\\fastapitest\\venv\\lib\\site-packages\\starlette\\middleware\\exceptions.py\", line 62, in __call__\n    |     await wrap_app_handling_exceptions(self.app, conn)(scope, receive, send)\n    |   File \"c:\\users\\jamie\\pycharmprojects\\fastapitest\\venv\\lib\\site-packages\\starlette\\_exception_handler.py\", line 53, in wrapped_app\n    |     raise exc\n    |   File \"c:\\users\\jamie\\pycharmprojects\\fastapitest\\venv\\lib\\site-packages\\starlette\\_exception_handler.py\", line 42, in wrapped_app\n    |     await app(scope, receive, sender)\n    |   File \"c:\\users\\jamie\\pycharmprojects\\fastapitest\\venv\\lib\\site-packages\\starlette\\routing.py\", line 714, in __call__\n    |     await self.middleware_stack(scope, receive, send)\n    |   File \"c:\\users\\jamie\\pycharmprojects\\fastapitest\\venv\\lib\\site-packages\\starlette\\routing.py\", line 734, in app\n    |     await route.handle(scope, receive, send)\n    |   File \"c:\\users\\jamie\\pycharmprojects\\fastapitest\\venv\\lib\\site-packages\\starlette\\routing.py\", line 288, in handle\n    |     await self.app(scope, receive, send)\n    |   File \"c:\\users\\jamie\\pycharmprojects\\fastapitest\\venv\\lib\\site-packages\\starlette\\routing.py\", line 76, in app\n    |     await wrap_app_handling_exceptions(app, request)(scope, receive, send)\n    |   File \"c:\\users\\jamie\\pycharmprojects\\fastapitest\\venv\\lib\\site-packages\\starlette\\_exception_handler.py\", line 53, in wrapped_app\n    |     raise exc\n    |   File \"c:\\users\\jamie\\pycharmprojects\\fastapitest\\venv\\lib\\site-packages\\starlette\\_exception_handler.py\", line 42, in wrapped_app\n    |     await app(scope, receive, sender)\n    |   File \"c:\\users\\jamie\\pycharmprojects\\fastapitest\\venv\\lib\\site-packages\\starlette\\routing.py\", line 73, in app\n    |     response = await f(request)\n    |   File \"c:\\users\\jamie\\pycharmprojects\\fastapitest\\venv\\lib\\site-packages\\fastapi\\routing.py\", line 301, in app\n    |     raw_response = await run_endpoint_function(\n    |   File \"c:\\users\\jamie\\pycharmprojects\\fastapitest\\venv\\lib\\site-packages\\fastapi\\routing.py\", line 212, in run_endpoint_function\n    |     return await dependant.call(**values)\n    |   File \"C:\\Users\\Jamie\\PycharmProjects\\fastapitest\\main.py\", line 122, in error\n    |     _ = 1 / 0  # Force an error to test logging\n    | ZeroDivisionError: division by zero\n    +------------------------------------\n\nDuring handling of the above exception, another exception occurred:\n\nTraceback (most recent call last):\n  File \"c:\\users\\jamie\\pycharmprojects\\fastapitest\\venv\\lib\\site-packages\\starlette\\middleware\\errors.py\", line 165, in __call__\n    await self.app(scope, receive, _send)\n  File \"c:\\users\\jamie\\pycharmprojects\\fastapitest\\venv\\lib\\site-packages\\starlette\\middleware\\base.py\", line 176, in __call__\n    with recv_stream, send_stream, collapse_excgroups():\n  File \"C:\\Program Files\\Python310\\lib\\contextlib.py\", line 153, in __exit__\n    self.gen.throw(typ, value, traceback)\n  File \"c:\\users\\jamie\\pycharmprojects\\fastapitest\\venv\\lib\\site-packages\\starlette\\_utils.py\", line 82, in collapse_excgroups\n    raise exc\n  File \"c:\\users\\jamie\\pycharmprojects\\fastapitest\\venv\\lib\\site-packages\\starlette\\middleware\\base.py\", line 178, in __call__\n    response = await self.dispatch_func(request, call_next)\n  File \"C:\\Users\\Jamie\\PycharmProjects\\fastapitest\\main.py\", line 68, in dispatch\n    response = await call_next(request)\n  File \"c:\\users\\jamie\\pycharmprojects\\fastapitest\\venv\\lib\\site-packages\\starlette\\middleware\\base.py\", line 156, in call_next\n    raise app_exc\n  File \"c:\\users\\jamie\\pycharmprojects\\fastapitest\\venv\\lib\\site-packages\\starlette\\middleware\\base.py\", line 141, in coro\n    await self.app(scope, receive_or_disconnect, send_no_error)\n  File \"c:\\users\\jamie\\pycharmprojects\\fastapitest\\venv\\lib\\site-packages\\starlette\\middleware\\exceptions.py\", line 62, in __call__\n    await wrap_app_handling_exceptions(self.app, conn)(scope, receive, send)\n  File \"c:\\users\\jamie\\pycharmprojects\\fastapitest\\venv\\lib\\site-packages\\starlette\\_exception_handler.py\", line 53, in wrapped_app\n    raise exc\n  File \"c:\\users\\jamie\\pycharmprojects\\fastapitest\\venv\\lib\\site-packages\\starlette\\_exception_handler.py\", line 42, in wrapped_app\n    await app(scope, receive, sender)\n  File \"c:\\users\\jamie\\pycharmprojects\\fastapitest\\venv\\lib\\site-packages\\starlette\\routing.py\", line 714, in __call__\n    await self.middleware_stack(scope, receive, send)\n  File \"c:\\users\\jamie\\pycharmprojects\\fastapitest\\venv\\lib\\site-packages\\starlette\\routing.py\", line 734, in app\n    await route.handle(scope, receive, send)\n  File \"c:\\users\\jamie\\pycharmprojects\\fastapitest\\venv\\lib\\site-packages\\starlette\\routing.py\", line 288, in handle\n    await self.app(scope, receive, send)\n  File \"c:\\users\\jamie\\pycharmprojects\\fastapitest\\venv\\lib\\site-packages\\starlette\\routing.py\", line 76, in app\n    await wrap_app_handling_exceptions(app, request)(scope, receive, send)\n  File \"c:\\users\\jamie\\pycharmprojects\\fastapitest\\venv\\lib\\site-packages\\starlette\\_exception_handler.py\", line 53, in wrapped_app\n    raise exc\n  File \"c:\\users\\jamie\\pycharmprojects\\fastapitest\\venv\\lib\\site-packages\\starlette\\_exception_handler.py\", line 42, in wrapped_app\n    await app(scope, receive, sender)\n  File \"c:\\users\\jamie\\pycharmprojects\\fastapitest\\venv\\lib\\site-packages\\starlette\\routing.py\", line 73, in app\n    response = await f(request)\n  File \"c:\\users\\jamie\\pycharmprojects\\fastapitest\\venv\\lib\\site-packages\\fastapi\\routing.py\", line 301, in app\n    raw_response = await run_endpoint_function(\n  File \"c:\\users\\jamie\\pycharmprojects\\fastapitest\\venv\\lib\\site-packages\\fastapi\\routing.py\", line 212, in run_endpoint_function\n    return await dependant.call(**values)\n  File \"C:\\Users\\Jamie\\PycharmProjects\\fastapitest\\main.py\", line 122, in error\n    _ = 1 / 0  # Force an error to test logging\nZeroDivisionError: division by zero\n", "logger": "error_logger"}
{"timestamp": "2025-05-08T12:28:02.383843+00:00", "level": "ERROR", "correlation_id": "ca88fcbd-35b8-4ad0-9638-655eb9c7db8e", "error": "division by zero", "message": "Unhandled Exception", "stack_trace": "  + Exception Group Traceback (most recent call last):\n  |   File \"c:\\users\\jamie\\pycharmprojects\\fastapitest\\venv\\lib\\site-packages\\starlette\\_utils.py\", line 76, in collapse_excgroups\n  |     yield\n  |   File \"c:\\users\\jamie\\pycharmprojects\\fastapitest\\venv\\lib\\site-packages\\starlette\\middleware\\base.py\", line 177, in __call__\n  |     async with anyio.create_task_group() as task_group:\n  |   File \"c:\\users\\jamie\\pycharmprojects\\fastapitest\\venv\\lib\\site-packages\\anyio\\_backends\\_asyncio.py\", line 772, in __aexit__\n  |     raise BaseExceptionGroup(\n  | exceptiongroup.ExceptionGroup: unhandled errors in a TaskGroup (1 sub-exception)\n  +-+---------------- 1 ----------------\n    | Traceback (most recent call last):\n    |   File \"c:\\users\\jamie\\pycharmprojects\\fastapitest\\venv\\lib\\site-packages\\starlette\\middleware\\errors.py\", line 165, in __call__\n    |     await self.app(scope, receive, _send)\n    |   File \"c:\\users\\jamie\\pycharmprojects\\fastapitest\\venv\\lib\\site-packages\\starlette\\middleware\\base.py\", line 176, in __call__\n    |     with recv_stream, send_stream, collapse_excgroups():\n    |   File \"C:\\Program Files\\Python310\\lib\\contextlib.py\", line 153, in __exit__\n    |     self.gen.throw(typ, value, traceback)\n    |   File \"c:\\users\\jamie\\pycharmprojects\\fastapitest\\venv\\lib\\site-packages\\starlette\\_utils.py\", line 82, in collapse_excgroups\n    |     raise exc\n    |   File \"c:\\users\\jamie\\pycharmprojects\\fastapitest\\venv\\lib\\site-packages\\starlette\\middleware\\base.py\", line 178, in __call__\n    |     response = await self.dispatch_func(request, call_next)\n    |   File \"C:\\Users\\Jamie\\PycharmProjects\\fastapitest\\main.py\", line 35, in dispatch\n    |     response = await call_next(request)\n    |   File \"c:\\users\\jamie\\pycharmprojects\\fastapitest\\venv\\lib\\site-packages\\starlette\\middleware\\base.py\", line 156, in call_next\n    |     raise app_exc\n    |   File \"c:\\users\\jamie\\pycharmprojects\\fastapitest\\venv\\lib\\site-packages\\starlette\\middleware\\base.py\", line 141, in coro\n    |     await self.app(scope, receive_or_disconnect, send_no_error)\n    |   File \"c:\\users\\jamie\\pycharmprojects\\fastapitest\\venv\\lib\\site-packages\\starlette\\middleware\\exceptions.py\", line 62, in __call__\n    |     await wrap_app_handling_exceptions(self.app, conn)(scope, receive, send)\n    |   File \"c:\\users\\jamie\\pycharmprojects\\fastapitest\\venv\\lib\\site-packages\\starlette\\_exception_handler.py\", line 53, in wrapped_app\n    |     raise exc\n    |   File \"c:\\users\\jamie\\pycharmprojects\\fastapitest\\venv\\lib\\site-packages\\starlette\\_exception_handler.py\", line 42, in wrapped_app\n    |     await app(scope, receive, sender)\n    |   File \"c:\\users\\jamie\\pycharmprojects\\fastapitest\\venv\\lib\\site-packages\\starlette\\routing.py\", line 714, in __call__\n    |     await self.middleware_stack(scope, receive, send)\n    |   File \"c:\\users\\jamie\\pycharmprojects\\fastapitest\\venv\\lib\\site-packages\\starlette\\routing.py\", line 734, in app\n    |     await route.handle(scope, receive, send)\n    |   File \"c:\\users\\jamie\\pycharmprojects\\fastapitest\\venv\\lib\\site-packages\\starlette\\routing.py\", line 288, in handle\n    |     await self.app(scope, receive, send)\n    |   File \"c:\\users\\jamie\\pycharmprojects\\fastapitest\\venv\\lib\\site-packages\\starlette\\routing.py\", line 76, in app\n    |     await wrap_app_handling_exceptions(app, request)(scope, receive, send)\n    |   File \"c:\\users\\jamie\\pycharmprojects\\fastapitest\\venv\\lib\\site-packages\\starlette\\_exception_handler.py\", line 53, in wrapped_app\n    |     raise exc\n    |   File \"c:\\users\\jamie\\pycharmprojects\\fastapitest\\venv\\lib\\site-packages\\starlette\\_exception_handler.py\", line 42, in wrapped_app\n    |     await app(scope, receive, sender)\n    |   File \"c:\\users\\jamie\\pycharmprojects\\fastapitest\\venv\\lib\\site-packages\\starlette\\routing.py\", line 73, in app\n    |     response = await f(request)\n    |   File \"c:\\users\\jamie\\pycharmprojects\\fastapitest\\venv\\lib\\site-packages\\fastapi\\routing.py\", line 301, in app\n    |     raw_response = await run_endpoint_function(\n    |   File \"c:\\users\\jamie\\pycharmprojects\\fastapitest\\venv\\lib\\site-packages\\fastapi\\routing.py\", line 212, in run_endpoint_function\n    |     return await dependant.call(**values)\n    |   File \"C:\\Users\\Jamie\\PycharmProjects\\fastapitest\\main.py\", line 89, in error\n    |     _ = 1 / 0  # Force an error to test logging\n    | ZeroDivisionError: division by zero\n    +------------------------------------\n\nDuring handling of the above exception, another exception occurred:\n\nTraceback (most recent call last):\n  File \"c:\\users\\jamie\\pycharmprojects\\fastapitest\\venv\\lib\\site-packages\\starlette\\middleware\\errors.py\", line 165, in __call__\n    await self.app(scope, receive, _send)\n  File \"c:\\users\\jamie\\pycharmprojects\\fastapitest\\venv\\lib\\site-packages\\starlette\\middleware\\base.py\", line 176, in __call__\n    with recv_stream, send_stream, collapse_excgroups():\n  File \"C:\\Program Files\\Python310\\lib\\contextlib.py\", line 153, in __exit__\n    self.gen.throw(typ, value, traceback)\n  File \"c:\\users\\jamie\\pycharmprojects\\fastapitest\\venv\\lib\\site-packages\\starlette\\_utils.py\", line 82, in collapse_excgroups\n    raise exc\n  File \"c:\\users\\jamie\\pycharmprojects\\fastapitest\\venv\\lib\\site-packages\\starlette\\middleware\\base.py\", line 178, in __call__\n    response = await self.dispatch_func(request, call_next)\n  File \"C:\\Users\\Jamie\\PycharmProjects\\fastapitest\\main.py\", line 35, in dispatch\n    response = await call_next(request)\n  File \"c:\\users\\jamie\\pycharmprojects\\fastapitest\\venv\\lib\\site-packages\\starlette\\middleware\\base.py\", line 156, in call_next\n    raise app_exc\n  File \"c:\\users\\jamie\\pycharmprojects\\fastapitest\\venv\\lib\\site-packages\\starlette\\middleware\\base.py\", line 141, in coro\n    await self.app(scope, receive_or_disconnect, send_no_error)\n  File \"c:\\users\\jamie\\pycharmprojects\\fastapitest\\venv\\lib\\site-packages\\starlette\\middleware\\exceptions.py\", line 62, in __call__\n    await wrap_app_handling_exceptions(self.app, conn)(scope, receive, send)\n  File \"c:\\users\\jamie\\pycharmprojects\\fastapitest\\venv\\lib\\site-packages\\starlette\\_exception_handler.py\", line 53, in wrapped_app\n    raise exc\n  File \"c:\\users\\jamie\\pycharmprojects\\fastapitest\\venv\\lib\\site-packages\\starlette\\_exception_handler.py\", line 42, in wrapped_app\n    await app(scope, receive, sender)\n  File \"c:\\users\\jamie\\pycharmprojects\\fastapitest\\venv\\lib\\site-packages\\starlette\\routing.py\", line 714, in __call__\n    await self.middleware_stack(scope, receive, send)\n  File \"c:\\users\\jamie\\pycharmprojects\\fastapitest\\venv\\lib\\site-packages\\starlette\\routing.py\", line 734, in app\n    await route.handle(scope, receive, send)\n  File \"c:\\users\\jamie\\pycharmprojects\\fastapitest\\venv\\lib\\site-packages\\starlette\\routing.py\", line 288, in handle\n    await self.app(scope, receive, send)\n  File \"c:\\users\\jamie\\pycharmprojects\\fastapitest\\venv\\lib\\site-packages\\starlette\\routing.py\", line 76, in app\n    await wrap_app_handling_exceptions(app, request)(scope, receive, send)\n  File \"c:\\users\\jamie\\pycharmprojects\\fastapitest\\venv\\lib\\site-packages\\starlette\\_exception_handler.py\", line 53, in wrapped_app\n    raise exc\n  File \"c:\\users\\jamie\\pycharmprojects\\fastapitest\\venv\\lib\\site-packages\\starlette\\_exception_handler.py\", line 42, in wrapped_app\n    await app(scope, receive, sender)\n  File \"c:\\users\\jamie\\pycharmprojects\\fastapitest\\venv\\lib\\site-packages\\starlette\\routing.py\", line 73, in app\n    response = await f(request)\n  File \"c:\\users\\jamie\\pycharmprojects\\fastapitest\\venv\\lib\\site-packages\\fastapi\\routing.py\", line 301, in app\n    raw_response = await run_endpoint_function(\n  File \"c:\\users\\jamie\\pycharmprojects\\fastapitest\\venv\\lib\\site-packages\\fastapi\\routing.py\", line 212, in run_endpoint_function\n    return await dependant.call(**values)\n  File \"C:\\Users\\Jamie\\PycharmProjects\\fastapitest\\main.py\", line 89, in error\n    _ = 1 / 0  # Force an error to test logging\nZeroDivisionError: division by zero\n", "logger": "error_logger"}
{"timestamp": "2025-05-08T17:30:07.325378+00:00", "level": "ERROR", "correlation_id": "8c07c7c2-8700-44e0-9e3c-7e39ab2b2427", "error": "'NoneType' object is not callable", "message": "Unhandled Exception", "stack_trace": "  + Exception Group Traceback (most recent call last):\n  |   File \"c:\\users\\jamie\\pycharmprojects\\fastapitest\\venv\\lib\\site-packages\\starlette\\_utils.py\", line 76, in collapse_excgroups\n  |     yield\n  |   File \"c:\\users\\jamie\\pycharmprojects\\fastapitest\\venv\\lib\\site-packages\\starlette\\middleware\\base.py\", line 177, in __call__\n  |     async with anyio.create_task_group() as task_group:\n  |   File \"c:\\users\\jamie\\pycharmprojects\\fastapitest\\venv\\lib\\site-packages\\anyio\\_backends\\_asyncio.py\", line 772, in __aexit__\n  |     raise BaseExceptionGroup(\n  | exceptiongroup.ExceptionGroup: unhandled errors in a TaskGroup (1 sub-exception)\n  +-+---------------- 1 ----------------\n    | Traceback (most recent call last):\n    |   File \"c:\\users\\jamie\\pycharmprojects\\fastapitest\\venv\\lib\\site-packages\\starlette\\middleware\\errors.py\", line 165, in __call__\n    |     await self.app(scope, receive, _send)\n    |   File \"c:\\users\\jamie\\pycharmprojects\\fastapitest\\venv\\lib\\site-packages\\starlette\\middleware\\base.py\", line 176, in __call__\n    |     with recv_stream, send_stream, collapse_excgroups():\n    |   File \"C:\\Program Files\\Python310\\lib\\contextlib.py\", line 153, in __exit__\n    |     self.gen.throw(typ, value, traceback)\n    |   File \"c:\\users\\jamie\\pycharmprojects\\fastapitest\\venv\\lib\\site-packages\\starlette\\_utils.py\", line 82, in collapse_excgroups\n    |     raise exc\n    |   File \"c:\\users\\jamie\\pycharmprojects\\fastapitest\\venv\\lib\\site-packages\\starlette\\middleware\\base.py\", line 179, in __call__\n    |     await response(scope, wrapped_receive, send)\n    | TypeError: 'NoneType' object is not callable\n    +------------------------------------\n\nDuring handling of the above exception, another exception occurred:\n\nTraceback (most recent call last):\n  File \"c:\\users\\jamie\\pycharmprojects\\fastapitest\\venv\\lib\\site-packages\\starlette\\middleware\\errors.py\", line 165, in __call__\n    await self.app(scope, receive, _send)\n  File \"c:\\users\\jamie\\pycharmprojects\\fastapitest\\venv\\lib\\site-packages\\starlette\\middleware\\base.py\", line 176, in __call__\n    with recv_stream, send_stream, collapse_excgroups():\n  File \"C:\\Program Files\\Python310\\lib\\contextlib.py\", line 153, in __exit__\n    self.gen.throw(typ, value, traceback)\n  File \"c:\\users\\jamie\\pycharmprojects\\fastapitest\\venv\\lib\\site-packages\\starlette\\_utils.py\", line 82, in collapse_excgroups\n    raise exc\n  File \"c:\\users\\jamie\\pycharmprojects\\fastapitest\\venv\\lib\\site-packages\\starlette\\middleware\\base.py\", line 179, in __call__\n    await response(scope, wrapped_receive, send)\nTypeError: 'NoneType' object is not callable\n", "logger": "error_logger"}
{"timestamp": "2025-05-08T17:30:08.357249+00:00", "level": "ERROR", "correlation_id": "a4ef0cfa-8125-4f01-9fcb-051c709df72d", "error": "'NoneType' object is not callable", "message": "Unhandled Exception", "stack_trace": "  + Exception Group Traceback (most recent call last):\n  |   File \"c:\\users\\jamie\\pycharmprojects\\fastapitest\\venv\\lib\\site-packages\\starlette\\_utils.py\", line 76, in collapse_excgroups\n  |     yield\n  |   File \"c:\\users\\jamie\\pycharmprojects\\fastapitest\\venv\\lib\\site-packages\\starlette\\middleware\\base.py\", line 177, in __call__\n  |     async with anyio.create_task_group() as task_group:\n  |   File \"c:\\users\\jamie\\pycharmprojects\\fastapitest\\venv\\lib\\site-packages\\anyio\\_backends\\_asyncio.py\", line 772, in __aexit__\n  |     raise BaseExceptionGroup(\n  | exceptiongroup.ExceptionGroup: unhandled errors in a TaskGroup (1 sub-exception)\n  +-+---------------- 1 ----------------\n    | Traceback (most recent call last):\n    |   File \"c:\\users\\jamie\\pycharmprojects\\fastapitest\\venv\\lib\\site-packages\\starlette\\middleware\\errors.py\", line 165, in __call__\n    |     await self.app(scope, receive, _send)\n    |   File \"c:\\users\\jamie\\pycharmprojects\\fastapitest\\venv\\lib\\site-packages\\starlette\\middleware\\base.py\", line 176, in __call__\n    |     with recv_stream, send_stream, collapse_excgroups():\n    |   File \"C:\\Program Files\\Python310\\lib\\contextlib.py\", line 153, in __exit__\n    |     self.gen.throw(typ, value, traceback)\n    |   File \"c:\\users\\jamie\\pycharmprojects\\fastapitest\\venv\\lib\\site-packages\\starlette\\_utils.py\", line 82, in collapse_excgroups\n    |     raise exc\n    |   File \"c:\\users\\jamie\\pycharmprojects\\fastapitest\\venv\\lib\\site-packages\\starlette\\middleware\\base.py\", line 179, in __call__\n    |     await response(scope, wrapped_receive, send)\n    | TypeError: 'NoneType' object is not callable\n    +------------------------------------\n\nDuring handling of the above exception, another exception occurred:\n\nTraceback (most recent call last):\n  File \"c:\\users\\jamie\\pycharmprojects\\fastapitest\\venv\\lib\\site-packages\\starlette\\middleware\\errors.py\", line 165, in __call__\n    await self.app(scope, receive, _send)\n  File \"c:\\users\\jamie\\pycharmprojects\\fastapitest\\venv\\lib\\site-packages\\starlette\\middleware\\base.py\", line 176, in __call__\n    with recv_stream, send_stream, collapse_excgroups():\n  File \"C:\\Program Files\\Python310\\lib\\contextlib.py\", line 153, in __exit__\n    self.gen.throw(typ, value, traceback)\n  File \"c:\\users\\jamie\\pycharmprojects\\fastapitest\\venv\\lib\\site-packages\\starlette\\_utils.py\", line 82, in collapse_excgroups\n    raise exc\n  File \"c:\\users\\jamie\\pycharmprojects\\fastapitest\\venv\\lib\\site-packages\\starlette\\middleware\\base.py\", line 179, in __call__\n    await response(scope, wrapped_receive, send)\nTypeError: 'NoneType' object is not callable\n", "logger": "error_logger"}
{"timestamp": "2025-05-08T17:31:21.260118+00:00", "level": "ERROR", "correlation_id": "0e86bcbc-80ad-46ef-83fe-8508d975b16b", "error": "division by zero", "message": "Unhandled Exception", "stack_trace": "  + Exception Group Traceback (most recent call last):\n  |   File \"c:\\users\\jamie\\pycharmprojects\\fastapitest\\venv\\lib\\site-packages\\starlette\\_utils.py\", line 76, in collapse_excgroups\n  |     yield\n  |   File \"c:\\users\\jamie\\pycharmprojects\\fastapitest\\venv\\lib\\site-packages\\starlette\\middleware\\base.py\", line 177, in __call__\n  |     async with anyio.create_task_group() as task_group:\n  |   File \"c:\\users\\jamie\\pycharmprojects\\fastapitest\\venv\\lib\\site-packages\\anyio\\_backends\\_asyncio.py\", line 772, in __aexit__\n  |     raise BaseExceptionGroup(\n  | exceptiongroup.ExceptionGroup: unhandled errors in a TaskGroup (1 sub-exception)\n  +-+---------------- 1 ----------------\n    | Traceback (most recent call last):\n    |   File \"c:\\users\\jamie\\pycharmprojects\\fastapitest\\venv\\lib\\site-packages\\starlette\\middleware\\errors.py\", line 165, in __call__\n    |     await self.app(scope, receive, _send)\n    |   File \"c:\\users\\jamie\\pycharmprojects\\fastapitest\\venv\\lib\\site-packages\\starlette\\middleware\\base.py\", line 176, in __call__\n    |     with recv_stream, send_stream, collapse_excgroups():\n    |   File \"C:\\Program Files\\Python310\\lib\\contextlib.py\", line 153, in __exit__\n    |     self.gen.throw(typ, value, traceback)\n    |   File \"c:\\users\\jamie\\pycharmprojects\\fastapitest\\venv\\lib\\site-packages\\starlette\\_utils.py\", line 82, in collapse_excgroups\n    |     raise exc\n    |   File \"c:\\users\\jamie\\pycharmprojects\\fastapitest\\venv\\lib\\site-packages\\starlette\\middleware\\base.py\", line 178, in __call__\n    |     response = await self.dispatch_func(request, call_next)\n    |   File \"C:\\Users\\Jamie\\PycharmProjects\\fastapitest\\main.py\", line 35, in dispatch\n    |     response = await call_next(request)\n    |   File \"c:\\users\\jamie\\pycharmprojects\\fastapitest\\venv\\lib\\site-packages\\starlette\\middleware\\base.py\", line 156, in call_next\n    |     raise app_exc\n    |   File \"c:\\users\\jamie\\pycharmprojects\\fastapitest\\venv\\lib\\site-packages\\starlette\\middleware\\base.py\", line 141, in coro\n    |     await self.app(scope, receive_or_disconnect, send_no_error)\n    |   File \"c:\\users\\jamie\\pycharmprojects\\fastapitest\\venv\\lib\\site-packages\\starlette\\middleware\\exceptions.py\", line 62, in __call__\n    |     await wrap_app_handling_exceptions(self.app, conn)(scope, receive, send)\n    |   File \"c:\\users\\jamie\\pycharmprojects\\fastapitest\\venv\\lib\\site-packages\\starlette\\_exception_handler.py\", line 53, in wrapped_app\n    |     raise exc\n    |   File \"c:\\users\\jamie\\pycharmprojects\\fastapitest\\venv\\lib\\site-packages\\starlette\\_exception_handler.py\", line 42, in wrapped_app\n    |     await app(scope, receive, sender)\n    |   File \"c:\\users\\jamie\\pycharmprojects\\fastapitest\\venv\\lib\\site-packages\\starlette\\routing.py\", line 714, in __call__\n    |     await self.middleware_stack(scope, receive, send)\n    |   File \"c:\\users\\jamie\\pycharmprojects\\fastapitest\\venv\\lib\\site-packages\\starlette\\routing.py\", line 734, in app\n    |     await route.handle(scope, receive, send)\n    |   File \"c:\\users\\jamie\\pycharmprojects\\fastapitest\\venv\\lib\\site-packages\\starlette\\routing.py\", line 288, in handle\n    |     await self.app(scope, receive, send)\n    |   File \"c:\\users\\jamie\\pycharmprojects\\fastapitest\\venv\\lib\\site-packages\\starlette\\routing.py\", line 76, in app\n    |     await wrap_app_handling_exceptions(app, request)(scope, receive, send)\n    |   File \"c:\\users\\jamie\\pycharmprojects\\fastapitest\\venv\\lib\\site-packages\\starlette\\_exception_handler.py\", line 53, in wrapped_app\n    |     raise exc\n    |   File \"c:\\users\\jamie\\pycharmprojects\\fastapitest\\venv\\lib\\site-packages\\starlette\\_exception_handler.py\", line 42, in wrapped_app\n    |     await app(scope, receive, sender)\n    |   File \"c:\\users\\jamie\\pycharmprojects\\fastapitest\\venv\\lib\\site-packages\\starlette\\routing.py\", line 73, in app\n    |     response = await f(request)\n    |   File \"c:\\users\\jamie\\pycharmprojects\\fastapitest\\venv\\lib\\site-packages\\fastapi\\routing.py\", line 301, in app\n    |     raw_response = await run_endpoint_function(\n    |   File \"c:\\users\\jamie\\pycharmprojects\\fastapitest\\venv\\lib\\site-packages\\fastapi\\routing.py\", line 212, in run_endpoint_function\n    |     return await dependant.call(**values)\n    |   File \"C:\\Users\\Jamie\\PycharmProjects\\fastapitest\\main.py\", line 89, in error\n    |     _ = 1 / 0  # Force an error to test logging\n    | ZeroDivisionError: division by zero\n    +------------------------------------\n\nDuring handling of the above exception, another exception occurred:\n\nTraceback (most recent call last):\n  File \"c:\\users\\jamie\\pycharmprojects\\fastapitest\\venv\\lib\\site-packages\\starlette\\middleware\\errors.py\", line 165, in __call__\n    await self.app(scope, receive, _send)\n  File \"c:\\users\\jamie\\pycharmprojects\\fastapitest\\venv\\lib\\site-packages\\starlette\\middleware\\base.py\", line 176, in __call__\n    with recv_stream, send_stream, collapse_excgroups():\n  File \"C:\\Program Files\\Python310\\lib\\contextlib.py\", line 153, in __exit__\n    self.gen.throw(typ, value, traceback)\n  File \"c:\\users\\jamie\\pycharmprojects\\fastapitest\\venv\\lib\\site-packages\\starlette\\_utils.py\", line 82, in collapse_excgroups\n    raise exc\n  File \"c:\\users\\jamie\\pycharmprojects\\fastapitest\\venv\\lib\\site-packages\\starlette\\middleware\\base.py\", line 178, in __call__\n    response = await self.dispatch_func(request, call_next)\n  File \"C:\\Users\\Jamie\\PycharmProjects\\fastapitest\\main.py\", line 35, in dispatch\n    response = await call_next(request)\n  File \"c:\\users\\jamie\\pycharmprojects\\fastapitest\\venv\\lib\\site-packages\\starlette\\middleware\\base.py\", line 156, in call_next\n    raise app_exc\n  File \"c:\\users\\jamie\\pycharmprojects\\fastapitest\\venv\\lib\\site-packages\\starlette\\middleware\\base.py\", line 141, in coro\n    await self.app(scope, receive_or_disconnect, send_no_error)\n  File \"c:\\users\\jamie\\pycharmprojects\\fastapitest\\venv\\lib\\site-packages\\starlette\\middleware\\exceptions.py\", line 62, in __call__\n    await wrap_app_handling_exceptions(self.app, conn)(scope, receive, send)\n  File \"c:\\users\\jamie\\pycharmprojects\\fastapitest\\venv\\lib\\site-packages\\starlette\\_exception_handler.py\", line 53, in wrapped_app\n    raise exc\n  File \"c:\\users\\jamie\\pycharmprojects\\fastapitest\\venv\\lib\\site-packages\\starlette\\_exception_handler.py\", line 42, in wrapped_app\n    await app(scope, receive, sender)\n  File \"c:\\users\\jamie\\pycharmprojects\\fastapitest\\venv\\lib\\site-packages\\starlette\\routing.py\", line 714, in __call__\n    await self.middleware_stack(scope, receive, send)\n  File \"c:\\users\\jamie\\pycharmprojects\\fastapitest\\venv\\lib\\site-packages\\starlette\\routing.py\", line 734, in app\n    await route.handle(scope, receive, send)\n  File \"c:\\users\\jamie\\pycharmprojects\\fastapitest\\venv\\lib\\site-packages\\starlette\\routing.py\", line 288, in handle\n    await self.app(scope, receive, send)\n  File \"c:\\users\\jamie\\pycharmprojects\\fastapitest\\venv\\lib\\site-packages\\starlette\\routing.py\", line 76, in app\n    await wrap_app_handling_exceptions(app, request)(scope, receive, send)\n  File \"c:\\users\\jamie\\pycharmprojects\\fastapitest\\venv\\lib\\site-packages\\starlette\\_exception_handler.py\", line 53, in wrapped_app\n    raise exc\n  File \"c:\\users\\jamie\\pycharmprojects\\fastapitest\\venv\\lib\\site-packages\\starlette\\_exception_handler.py\", line 42, in wrapped_app\n    await app(scope, receive, sender)\n  File \"c:\\users\\jamie\\pycharmprojects\\fastapitest\\venv\\lib\\site-packages\\starlette\\routing.py\", line 73, in app\n    response = await f(request)\n  File \"c:\\users\\jamie\\pycharmprojects\\fastapitest\\venv\\lib\\site-packages\\fastapi\\routing.py\", line 301, in app\n    raw_response = await run_endpoint_function(\n  File \"c:\\users\\jamie\\pycharmprojects\\fastapitest\\venv\\lib\\site-packages\\fastapi\\routing.py\", line 212, in run_endpoint_function\n    return await dependant.call(**values)\n  File \"C:\\Users\\Jamie\\PycharmProjects\\fastapitest\\main.py\", line 89, in error\n    _ = 1 / 0  # Force an error to test logging\nZeroDivisionError: division by zero\n", "logger": "error_logger"}
{"timestamp": "2025-05-08T17:32:12.590445+00:00", "level": "ERROR", "correlation_id": "5ee70c28-1d14-442e-9ec1-12805ba5d7d3", "error": "division by zero", "message": "Unhandled Exception", "stack_trace": "  + Exception Group Traceback (most recent call last):\n  |   File \"c:\\users\\jamie\\pycharmprojects\\fastapitest\\venv\\lib\\site-packages\\starlette\\_utils.py\", line 76, in collapse_excgroups\n  |     yield\n  |   File \"c:\\users\\jamie\\pycharmprojects\\fastapitest\\venv\\lib\\site-packages\\starlette\\middleware\\base.py\", line 177, in __call__\n  |     async with anyio.create_task_group() as task_group:\n  |   File \"c:\\users\\jamie\\pycharmprojects\\fastapitest\\venv\\lib\\site-packages\\anyio\\_backends\\_asyncio.py\", line 772, in __aexit__\n  |     raise BaseExceptionGroup(\n  | exceptiongroup.ExceptionGroup: unhandled errors in a TaskGroup (1 sub-exception)\n  +-+---------------- 1 ----------------\n    | Traceback (most recent call last):\n    |   File \"c:\\users\\jamie\\pycharmprojects\\fastapitest\\venv\\lib\\site-packages\\starlette\\middleware\\errors.py\", line 165, in __call__\n    |     await self.app(scope, receive, _send)\n    |   File \"c:\\users\\jamie\\pycharmprojects\\fastapitest\\venv\\lib\\site-packages\\starlette\\middleware\\base.py\", line 176, in __call__\n    |     with recv_stream, send_stream, collapse_excgroups():\n    |   File \"C:\\Program Files\\Python310\\lib\\contextlib.py\", line 153, in __exit__\n    |     self.gen.throw(typ, value, traceback)\n    |   File \"c:\\users\\jamie\\pycharmprojects\\fastapitest\\venv\\lib\\site-packages\\starlette\\_utils.py\", line 82, in collapse_excgroups\n    |     raise exc\n    |   File \"c:\\users\\jamie\\pycharmprojects\\fastapitest\\venv\\lib\\site-packages\\starlette\\middleware\\base.py\", line 178, in __call__\n    |     response = await self.dispatch_func(request, call_next)\n    |   File \"C:\\Users\\Jamie\\PycharmProjects\\fastapitest\\main.py\", line 35, in dispatch\n    |     response = await call_next(request)\n    |   File \"c:\\users\\jamie\\pycharmprojects\\fastapitest\\venv\\lib\\site-packages\\starlette\\middleware\\base.py\", line 156, in call_next\n    |     raise app_exc\n    |   File \"c:\\users\\jamie\\pycharmprojects\\fastapitest\\venv\\lib\\site-packages\\starlette\\middleware\\base.py\", line 141, in coro\n    |     await self.app(scope, receive_or_disconnect, send_no_error)\n    |   File \"c:\\users\\jamie\\pycharmprojects\\fastapitest\\venv\\lib\\site-packages\\starlette\\middleware\\exceptions.py\", line 62, in __call__\n    |     await wrap_app_handling_exceptions(self.app, conn)(scope, receive, send)\n    |   File \"c:\\users\\jamie\\pycharmprojects\\fastapitest\\venv\\lib\\site-packages\\starlette\\_exception_handler.py\", line 53, in wrapped_app\n    |     raise exc\n    |   File \"c:\\users\\jamie\\pycharmprojects\\fastapitest\\venv\\lib\\site-packages\\starlette\\_exception_handler.py\", line 42, in wrapped_app\n    |     await app(scope, receive, sender)\n    |   File \"c:\\users\\jamie\\pycharmprojects\\fastapitest\\venv\\lib\\site-packages\\starlette\\routing.py\", line 714, in __call__\n    |     await self.middleware_stack(scope, receive, send)\n    |   File \"c:\\users\\jamie\\pycharmprojects\\fastapitest\\venv\\lib\\site-packages\\starlette\\routing.py\", line 734, in app\n    |     await route.handle(scope, receive, send)\n    |   File \"c:\\users\\jamie\\pycharmprojects\\fastapitest\\venv\\lib\\site-packages\\starlette\\routing.py\", line 288, in handle\n    |     await self.app(scope, receive, send)\n    |   File \"c:\\users\\jamie\\pycharmprojects\\fastapitest\\venv\\lib\\site-packages\\starlette\\routing.py\", line 76, in app\n    |     await wrap_app_handling_exceptions(app, request)(scope, receive, send)\n    |   File \"c:\\users\\jamie\\pycharmprojects\\fastapitest\\venv\\lib\\site-packages\\starlette\\_exception_handler.py\", line 53, in wrapped_app\n    |     raise exc\n    |   File \"c:\\users\\jamie\\pycharmprojects\\fastapitest\\venv\\lib\\site-packages\\starlette\\_exception_handler.py\", line 42, in wrapped_app\n    |     await app(scope, receive, sender)\n    |   File \"c:\\users\\jamie\\pycharmprojects\\fastapitest\\venv\\lib\\site-packages\\starlette\\routing.py\", line 73, in app\n    |     response = await f(request)\n    |   File \"c:\\users\\jamie\\pycharmprojects\\fastapitest\\venv\\lib\\site-packages\\fastapi\\routing.py\", line 301, in app\n    |     raw_response = await run_endpoint_function(\n    |   File \"c:\\users\\jamie\\pycharmprojects\\fastapitest\\venv\\lib\\site-packages\\fastapi\\routing.py\", line 212, in run_endpoint_function\n    |     return await dependant.call(**values)\n    |   File \"C:\\Users\\Jamie\\PycharmProjects\\fastapitest\\main.py\", line 89, in error\n    |     _ = 1 / 0  # Force an error to test logging\n    | ZeroDivisionError: division by zero\n    +------------------------------------\n\nDuring handling of the above exception, another exception occurred:\n\nTraceback (most recent call last):\n  File \"c:\\users\\jamie\\pycharmprojects\\fastapitest\\venv\\lib\\site-packages\\starlette\\middleware\\errors.py\", line 165, in __call__\n    await self.app(scope, receive, _send)\n  File \"c:\\users\\jamie\\pycharmprojects\\fastapitest\\venv\\lib\\site-packages\\starlette\\middleware\\base.py\", line 176, in __call__\n    with recv_stream, send_stream, collapse_excgroups():\n  File \"C:\\Program Files\\Python310\\lib\\contextlib.py\", line 153, in __exit__\n    self.gen.throw(typ, value, traceback)\n  File \"c:\\users\\jamie\\pycharmprojects\\fastapitest\\venv\\lib\\site-packages\\starlette\\_utils.py\", line 82, in collapse_excgroups\n    raise exc\n  File \"c:\\users\\jamie\\pycharmprojects\\fastapitest\\venv\\lib\\site-packages\\starlette\\middleware\\base.py\", line 178, in __call__\n    response = await self.dispatch_func(request, call_next)\n  File \"C:\\Users\\Jamie\\PycharmProjects\\fastapitest\\main.py\", line 35, in dispatch\n    response = await call_next(request)\n  File \"c:\\users\\jamie\\pycharmprojects\\fastapitest\\venv\\lib\\site-packages\\starlette\\middleware\\base.py\", line 156, in call_next\n    raise app_exc\n  File \"c:\\users\\jamie\\pycharmprojects\\fastapitest\\venv\\lib\\site-packages\\starlette\\middleware\\base.py\", line 141, in coro\n    await self.app(scope, receive_or_disconnect, send_no_error)\n  File \"c:\\users\\jamie\\pycharmprojects\\fastapitest\\venv\\lib\\site-packages\\starlette\\middleware\\exceptions.py\", line 62, in __call__\n    await wrap_app_handling_exceptions(self.app, conn)(scope, receive, send)\n  File \"c:\\users\\jamie\\pycharmprojects\\fastapitest\\venv\\lib\\site-packages\\starlette\\_exception_handler.py\", line 53, in wrapped_app\n    raise exc\n  File \"c:\\users\\jamie\\pycharmprojects\\fastapitest\\venv\\lib\\site-packages\\starlette\\_exception_handler.py\", line 42, in wrapped_app\n    await app(scope, receive, sender)\n  File \"c:\\users\\jamie\\pycharmprojects\\fastapitest\\venv\\lib\\site-packages\\starlette\\routing.py\", line 714, in __call__\n    await self.middleware_stack(scope, receive, send)\n  File \"c:\\users\\jamie\\pycharmprojects\\fastapitest\\venv\\lib\\site-packages\\starlette\\routing.py\", line 734, in app\n    await route.handle(scope, receive, send)\n  File \"c:\\users\\jamie\\pycharmprojects\\fastapitest\\venv\\lib\\site-packages\\starlette\\routing.py\", line 288, in handle\n    await self.app(scope, receive, send)\n  File \"c:\\users\\jamie\\pycharmprojects\\fastapitest\\venv\\lib\\site-packages\\starlette\\routing.py\", line 76, in app\n    await wrap_app_handling_exceptions(app, request)(scope, receive, send)\n  File \"c:\\users\\jamie\\pycharmprojects\\fastapitest\\venv\\lib\\site-packages\\starlette\\_exception_handler.py\", line 53, in wrapped_app\n    raise exc\n  File \"c:\\users\\jamie\\pycharmprojects\\fastapitest\\venv\\lib\\site-packages\\starlette\\_exception_handler.py\", line 42, in wrapped_app\n    await app(scope, receive, sender)\n  File \"c:\\users\\jamie\\pycharmprojects\\fastapitest\\venv\\lib\\site-packages\\starlette\\routing.py\", line 73, in app\n    response = await f(request)\n  File \"c:\\users\\jamie\\pycharmprojects\\fastapitest\\venv\\lib\\site-packages\\fastapi\\routing.py\", line 301, in app\n    raw_response = await run_endpoint_function(\n  File \"c:\\users\\jamie\\pycharmprojects\\fastapitest\\venv\\lib\\site-packages\\fastapi\\routing.py\", line 212, in run_endpoint_function\n    return await dependant.call(**values)\n  File \"C:\\Users\\Jamie\\PycharmProjects\\fastapitest\\main.py\", line 89, in error\n    _ = 1 / 0  # Force an error to test logging\nZeroDivisionError: division by zero\n", "logger": "error_logger"}
{"timestamp": "2025-05-08T17:33:20.875580+00:00", "level": "ERROR", "correlation_id": "8ee5fb91-2101-4d84-9f63-cc48d18de9b6", "error": "list index out of range", "message": "Unhandled Exception", "stack_trace": "  + Exception Group Traceback (most recent call last):\n  |   File \"c:\\users\\jamie\\pycharmprojects\\fastapitest\\venv\\lib\\site-packages\\starlette\\_utils.py\", line 76, in collapse_excgroups\n  |     yield\n  |   File \"c:\\users\\jamie\\pycharmprojects\\fastapitest\\venv\\lib\\site-packages\\starlette\\middleware\\base.py\", line 177, in __call__\n  |     async with anyio.create_task_group() as task_group:\n  |   File \"c:\\users\\jamie\\pycharmprojects\\fastapitest\\venv\\lib\\site-packages\\anyio\\_backends\\_asyncio.py\", line 772, in __aexit__\n  |     raise BaseExceptionGroup(\n  | exceptiongroup.ExceptionGroup: unhandled errors in a TaskGroup (1 sub-exception)\n  +-+---------------- 1 ----------------\n    | Traceback (most recent call last):\n    |   File \"c:\\users\\jamie\\pycharmprojects\\fastapitest\\venv\\lib\\site-packages\\starlette\\middleware\\errors.py\", line 165, in __call__\n    |     await self.app(scope, receive, _send)\n    |   File \"c:\\users\\jamie\\pycharmprojects\\fastapitest\\venv\\lib\\site-packages\\starlette\\middleware\\base.py\", line 176, in __call__\n    |     with recv_stream, send_stream, collapse_excgroups():\n    |   File \"C:\\Program Files\\Python310\\lib\\contextlib.py\", line 153, in __exit__\n    |     self.gen.throw(typ, value, traceback)\n    |   File \"c:\\users\\jamie\\pycharmprojects\\fastapitest\\venv\\lib\\site-packages\\starlette\\_utils.py\", line 82, in collapse_excgroups\n    |     raise exc\n    |   File \"c:\\users\\jamie\\pycharmprojects\\fastapitest\\venv\\lib\\site-packages\\starlette\\middleware\\base.py\", line 178, in __call__\n    |     response = await self.dispatch_func(request, call_next)\n    |   File \"C:\\Users\\Jamie\\PycharmProjects\\fastapitest\\main.py\", line 35, in dispatch\n    |     response = await call_next(request)\n    |   File \"c:\\users\\jamie\\pycharmprojects\\fastapitest\\venv\\lib\\site-packages\\starlette\\middleware\\base.py\", line 156, in call_next\n    |     raise app_exc\n    |   File \"c:\\users\\jamie\\pycharmprojects\\fastapitest\\venv\\lib\\site-packages\\starlette\\middleware\\base.py\", line 141, in coro\n    |     await self.app(scope, receive_or_disconnect, send_no_error)\n    |   File \"c:\\users\\jamie\\pycharmprojects\\fastapitest\\venv\\lib\\site-packages\\starlette\\middleware\\exceptions.py\", line 62, in __call__\n    |     await wrap_app_handling_exceptions(self.app, conn)(scope, receive, send)\n    |   File \"c:\\users\\jamie\\pycharmprojects\\fastapitest\\venv\\lib\\site-packages\\starlette\\_exception_handler.py\", line 53, in wrapped_app\n    |     raise exc\n    |   File \"c:\\users\\jamie\\pycharmprojects\\fastapitest\\venv\\lib\\site-packages\\starlette\\_exception_handler.py\", line 42, in wrapped_app\n    |     await app(scope, receive, sender)\n    |   File \"c:\\users\\jamie\\pycharmprojects\\fastapitest\\venv\\lib\\site-packages\\starlette\\routing.py\", line 714, in __call__\n    |     await self.middleware_stack(scope, receive, send)\n    |   File \"c:\\users\\jamie\\pycharmprojects\\fastapitest\\venv\\lib\\site-packages\\starlette\\routing.py\", line 734, in app\n    |     await route.handle(scope, receive, send)\n    |   File \"c:\\users\\jamie\\pycharmprojects\\fastapitest\\venv\\lib\\site-packages\\starlette\\routing.py\", line 288, in handle\n    |     await self.app(scope, receive, send)\n    |   File \"c:\\users\\jamie\\pycharmprojects\\fastapitest\\venv\\lib\\site-packages\\starlette\\routing.py\", line 76, in app\n    |     await wrap_app_handling_exceptions(app, request)(scope, receive, send)\n    |   File \"c:\\users\\jamie\\pycharmprojects\\fastapitest\\venv\\lib\\site-packages\\starlette\\_exception_handler.py\", line 53, in wrapped_app\n    |     raise exc\n    |   File \"c:\\users\\jamie\\pycharmprojects\\fastapitest\\venv\\lib\\site-packages\\starlette\\_exception_handler.py\", line 42, in wrapped_app\n    |     await app(scope, receive, sender)\n    |   File \"c:\\users\\jamie\\pycharmprojects\\fastapitest\\venv\\lib\\site-packages\\starlette\\routing.py\", line 73, in app\n    |     response = await f(request)\n    |   File \"c:\\users\\jamie\\pycharmprojects\\fastapitest\\venv\\lib\\site-packages\\fastapi\\routing.py\", line 301, in app\n    |     raw_response = await run_endpoint_function(\n    |   File \"c:\\users\\jamie\\pycharmprojects\\fastapitest\\venv\\lib\\site-packages\\fastapi\\routing.py\", line 212, in run_endpoint_function\n    |     return await dependant.call(**values)\n    |   File \"C:\\Users\\Jamie\\PycharmProjects\\fastapitest\\main.py\", line 97, in error\n    |     example[i]\n    | IndexError: list index out of range\n    +------------------------------------\n\nDuring handling of the above exception, another exception occurred:\n\nTraceback (most recent call last):\n  File \"c:\\users\\jamie\\pycharmprojects\\fastapitest\\venv\\lib\\site-packages\\starlette\\middleware\\errors.py\", line 165, in __call__\n    await self.app(scope, receive, _send)\n  File \"c:\\users\\jamie\\pycharmprojects\\fastapitest\\venv\\lib\\site-packages\\starlette\\middleware\\base.py\", line 176, in __call__\n    with recv_stream, send_stream, collapse_excgroups():\n  File \"C:\\Program Files\\Python310\\lib\\contextlib.py\", line 153, in __exit__\n    self.gen.throw(typ, value, traceback)\n  File \"c:\\users\\jamie\\pycharmprojects\\fastapitest\\venv\\lib\\site-packages\\starlette\\_utils.py\", line 82, in collapse_excgroups\n    raise exc\n  File \"c:\\users\\jamie\\pycharmprojects\\fastapitest\\venv\\lib\\site-packages\\starlette\\middleware\\base.py\", line 178, in __call__\n    response = await self.dispatch_func(request, call_next)\n  File \"C:\\Users\\Jamie\\PycharmProjects\\fastapitest\\main.py\", line 35, in dispatch\n    response = await call_next(request)\n  File \"c:\\users\\jamie\\pycharmprojects\\fastapitest\\venv\\lib\\site-packages\\starlette\\middleware\\base.py\", line 156, in call_next\n    raise app_exc\n  File \"c:\\users\\jamie\\pycharmprojects\\fastapitest\\venv\\lib\\site-packages\\starlette\\middleware\\base.py\", line 141, in coro\n    await self.app(scope, receive_or_disconnect, send_no_error)\n  File \"c:\\users\\jamie\\pycharmprojects\\fastapitest\\venv\\lib\\site-packages\\starlette\\middleware\\exceptions.py\", line 62, in __call__\n    await wrap_app_handling_exceptions(self.app, conn)(scope, receive, send)\n  File \"c:\\users\\jamie\\pycharmprojects\\fastapitest\\venv\\lib\\site-packages\\starlette\\_exception_handler.py\", line 53, in wrapped_app\n    raise exc\n  File \"c:\\users\\jamie\\pycharmprojects\\fastapitest\\venv\\lib\\site-packages\\starlette\\_exception_handler.py\", line 42, in wrapped_app\n    await app(scope, receive, sender)\n  File \"c:\\users\\jamie\\pycharmprojects\\fastapitest\\venv\\lib\\site-packages\\starlette\\routing.py\", line 714, in __call__\n    await self.middleware_stack(scope, receive, send)\n  File \"c:\\users\\jamie\\pycharmprojects\\fastapitest\\venv\\lib\\site-packages\\starlette\\routing.py\", line 734, in app\n    await route.handle(scope, receive, send)\n  File \"c:\\users\\jamie\\pycharmprojects\\fastapitest\\venv\\lib\\site-packages\\starlette\\routing.py\", line 288, in handle\n    await self.app(scope, receive, send)\n  File \"c:\\users\\jamie\\pycharmprojects\\fastapitest\\venv\\lib\\site-packages\\starlette\\routing.py\", line 76, in app\n    await wrap_app_handling_exceptions(app, request)(scope, receive, send)\n  File \"c:\\users\\jamie\\pycharmprojects\\fastapitest\\venv\\lib\\site-packages\\starlette\\_exception_handler.py\", line 53, in wrapped_app\n    raise exc\n  File \"c:\\users\\jamie\\pycharmprojects\\fastapitest\\venv\\lib\\site-packages\\starlette\\_exception_handler.py\", line 42, in wrapped_app\n    await app(scope, receive, sender)\n  File \"c:\\users\\jamie\\pycharmprojects\\fastapitest\\venv\\lib\\site-packages\\starlette\\routing.py\", line 73, in app\n    response = await f(request)\n  File \"c:\\users\\jamie\\pycharmprojects\\fastapitest\\venv\\lib\\site-packages\\fastapi\\routing.py\", line 301, in app\n    raw_response = await run_endpoint_function(\n  File \"c:\\users\\jamie\\pycharmprojects\\fastapitest\\venv\\lib\\site-packages\\fastapi\\routing.py\", line 212, in run_endpoint_function\n    return await dependant.call(**values)\n  File \"C:\\Users\\Jamie\\PycharmProjects\\fastapitest\\main.py\", line 97, in error\n    example[i]\nIndexError: list index out of range\n", "logger": "error_logger"}
{"timestamp": "2025-05-08T17:39:50.655448+00:00", "level": "ERROR", "correlation_id": "00f753e2-30f7-45a3-b999-21a2691d7bcb", "response_time": 0.005000591278076172, "error": "list index out of range", "message": "Unhandled Exception", "stack_trace": "  + Exception Group Traceback (most recent call last):\n  |   File \"c:\\users\\jamie\\pycharmprojects\\fastapitest\\venv\\lib\\site-packages\\starlette\\_utils.py\", line 76, in collapse_excgroups\n  |     yield\n  |   File \"c:\\users\\jamie\\pycharmprojects\\fastapitest\\venv\\lib\\site-packages\\starlette\\middleware\\base.py\", line 177, in __call__\n  |     async with anyio.create_task_group() as task_group:\n  |   File \"c:\\users\\jamie\\pycharmprojects\\fastapitest\\venv\\lib\\site-packages\\anyio\\_backends\\_asyncio.py\", line 772, in __aexit__\n  |     raise BaseExceptionGroup(\n  | exceptiongroup.ExceptionGroup: unhandled errors in a TaskGroup (1 sub-exception)\n  +-+---------------- 1 ----------------\n    | Traceback (most recent call last):\n    |   File \"c:\\users\\jamie\\pycharmprojects\\fastapitest\\venv\\lib\\site-packages\\starlette\\middleware\\errors.py\", line 165, in __call__\n    |     await self.app(scope, receive, _send)\n    |   File \"c:\\users\\jamie\\pycharmprojects\\fastapitest\\venv\\lib\\site-packages\\starlette\\middleware\\base.py\", line 176, in __call__\n    |     with recv_stream, send_stream, collapse_excgroups():\n    |   File \"C:\\Program Files\\Python310\\lib\\contextlib.py\", line 153, in __exit__\n    |     self.gen.throw(typ, value, traceback)\n    |   File \"c:\\users\\jamie\\pycharmprojects\\fastapitest\\venv\\lib\\site-packages\\starlette\\_utils.py\", line 82, in collapse_excgroups\n    |     raise exc\n    |   File \"c:\\users\\jamie\\pycharmprojects\\fastapitest\\venv\\lib\\site-packages\\starlette\\middleware\\base.py\", line 178, in __call__\n    |     response = await self.dispatch_func(request, call_next)\n    |   File \"C:\\Users\\Jamie\\PycharmProjects\\fastapitest\\main.py\", line 32, in dispatch\n    |     response = await call_next(request)\n    |   File \"c:\\users\\jamie\\pycharmprojects\\fastapitest\\venv\\lib\\site-packages\\starlette\\middleware\\base.py\", line 156, in call_next\n    |     raise app_exc\n    |   File \"c:\\users\\jamie\\pycharmprojects\\fastapitest\\venv\\lib\\site-packages\\starlette\\middleware\\base.py\", line 141, in coro\n    |     await self.app(scope, receive_or_disconnect, send_no_error)\n    |   File \"c:\\users\\jamie\\pycharmprojects\\fastapitest\\venv\\lib\\site-packages\\starlette\\middleware\\exceptions.py\", line 62, in __call__\n    |     await wrap_app_handling_exceptions(self.app, conn)(scope, receive, send)\n    |   File \"c:\\users\\jamie\\pycharmprojects\\fastapitest\\venv\\lib\\site-packages\\starlette\\_exception_handler.py\", line 53, in wrapped_app\n    |     raise exc\n    |   File \"c:\\users\\jamie\\pycharmprojects\\fastapitest\\venv\\lib\\site-packages\\starlette\\_exception_handler.py\", line 42, in wrapped_app\n    |     await app(scope, receive, sender)\n    |   File \"c:\\users\\jamie\\pycharmprojects\\fastapitest\\venv\\lib\\site-packages\\starlette\\routing.py\", line 714, in __call__\n    |     await self.middleware_stack(scope, receive, send)\n    |   File \"c:\\users\\jamie\\pycharmprojects\\fastapitest\\venv\\lib\\site-packages\\starlette\\routing.py\", line 734, in app\n    |     await route.handle(scope, receive, send)\n    |   File \"c:\\users\\jamie\\pycharmprojects\\fastapitest\\venv\\lib\\site-packages\\starlette\\routing.py\", line 288, in handle\n    |     await self.app(scope, receive, send)\n    |   File \"c:\\users\\jamie\\pycharmprojects\\fastapitest\\venv\\lib\\site-packages\\starlette\\routing.py\", line 76, in app\n    |     await wrap_app_handling_exceptions(app, request)(scope, receive, send)\n    |   File \"c:\\users\\jamie\\pycharmprojects\\fastapitest\\venv\\lib\\site-packages\\starlette\\_exception_handler.py\", line 53, in wrapped_app\n    |     raise exc\n    |   File \"c:\\users\\jamie\\pycharmprojects\\fastapitest\\venv\\lib\\site-packages\\starlette\\_exception_handler.py\", line 42, in wrapped_app\n    |     await app(scope, receive, sender)\n    |   File \"c:\\users\\jamie\\pycharmprojects\\fastapitest\\venv\\lib\\site-packages\\starlette\\routing.py\", line 73, in app\n    |     response = await f(request)\n    |   File \"c:\\users\\jamie\\pycharmprojects\\fastapitest\\venv\\lib\\site-packages\\fastapi\\routing.py\", line 301, in app\n    |     raw_response = await run_endpoint_function(\n    |   File \"c:\\users\\jamie\\pycharmprojects\\fastapitest\\venv\\lib\\site-packages\\fastapi\\routing.py\", line 212, in run_endpoint_function\n    |     return await dependant.call(**values)\n    |   File \"C:\\Users\\Jamie\\PycharmProjects\\fastapitest\\main.py\", line 89, in error\n    |     example[i]\n    | IndexError: list index out of range\n    +------------------------------------\n\nDuring handling of the above exception, another exception occurred:\n\nTraceback (most recent call last):\n  File \"c:\\users\\jamie\\pycharmprojects\\fastapitest\\venv\\lib\\site-packages\\starlette\\middleware\\errors.py\", line 165, in __call__\n    await self.app(scope, receive, _send)\n  File \"c:\\users\\jamie\\pycharmprojects\\fastapitest\\venv\\lib\\site-packages\\starlette\\middleware\\base.py\", line 176, in __call__\n    with recv_stream, send_stream, collapse_excgroups():\n  File \"C:\\Program Files\\Python310\\lib\\contextlib.py\", line 153, in __exit__\n    self.gen.throw(typ, value, traceback)\n  File \"c:\\users\\jamie\\pycharmprojects\\fastapitest\\venv\\lib\\site-packages\\starlette\\_utils.py\", line 82, in collapse_excgroups\n    raise exc\n  File \"c:\\users\\jamie\\pycharmprojects\\fastapitest\\venv\\lib\\site-packages\\starlette\\middleware\\base.py\", line 178, in __call__\n    response = await self.dispatch_func(request, call_next)\n  File \"C:\\Users\\Jamie\\PycharmProjects\\fastapitest\\main.py\", line 32, in dispatch\n    response = await call_next(request)\n  File \"c:\\users\\jamie\\pycharmprojects\\fastapitest\\venv\\lib\\site-packages\\starlette\\middleware\\base.py\", line 156, in call_next\n    raise app_exc\n  File \"c:\\users\\jamie\\pycharmprojects\\fastapitest\\venv\\lib\\site-packages\\starlette\\middleware\\base.py\", line 141, in coro\n    await self.app(scope, receive_or_disconnect, send_no_error)\n  File \"c:\\users\\jamie\\pycharmprojects\\fastapitest\\venv\\lib\\site-packages\\starlette\\middleware\\exceptions.py\", line 62, in __call__\n    await wrap_app_handling_exceptions(self.app, conn)(scope, receive, send)\n  File \"c:\\users\\jamie\\pycharmprojects\\fastapitest\\venv\\lib\\site-packages\\starlette\\_exception_handler.py\", line 53, in wrapped_app\n    raise exc\n  File \"c:\\users\\jamie\\pycharmprojects\\fastapitest\\venv\\lib\\site-packages\\starlette\\_exception_handler.py\", line 42, in wrapped_app\n    await app(scope, receive, sender)\n  File \"c:\\users\\jamie\\pycharmprojects\\fastapitest\\venv\\lib\\site-packages\\starlette\\routing.py\", line 714, in __call__\n    await self.middleware_stack(scope, receive, send)\n  File \"c:\\users\\jamie\\pycharmprojects\\fastapitest\\venv\\lib\\site-packages\\starlette\\routing.py\", line 734, in app\n    await route.handle(scope, receive, send)\n  File \"c:\\users\\jamie\\pycharmprojects\\fastapitest\\venv\\lib\\site-packages\\starlette\\routing.py\", line 288, in handle\n    await self.app(scope, receive, send)\n  File \"c:\\users\\jamie\\pycharmprojects\\fastapitest\\venv\\lib\\site-packages\\starlette\\routing.py\", line 76, in app\n    await wrap_app_handling_exceptions(app, request)(scope, receive, send)\n  File \"c:\\users\\jamie\\pycharmprojects\\fastapitest\\venv\\lib\\site-packages\\starlette\\_exception_handler.py\", line 53, in wrapped_app\n    raise exc\n  File \"c:\\users\\jamie\\pycharmprojects\\fastapitest\\venv\\lib\\site-packages\\starlette\\_exception_handler.py\", line 42, in wrapped_app\n    await app(scope, receive, sender)\n  File \"c:\\users\\jamie\\pycharmprojects\\fastapitest\\venv\\lib\\site-packages\\starlette\\routing.py\", line 73, in app\n    response = await f(request)\n  File \"c:\\users\\jamie\\pycharmprojects\\fastapitest\\venv\\lib\\site-packages\\fastapi\\routing.py\", line 301, in app\n    raw_response = await run_endpoint_function(\n  File \"c:\\users\\jamie\\pycharmprojects\\fastapitest\\venv\\lib\\site-packages\\fastapi\\routing.py\", line 212, in run_endpoint_function\n    return await dependant.call(**values)\n  File \"C:\\Users\\Jamie\\PycharmProjects\\fastapitest\\main.py\", line 89, in error\n    example[i]\nIndexError: list index out of range\n", "logger": "error_logger"}
{"timestamp": "2025-05-08T17:54:03.307227+00:00", "level": "ERROR", "correlation_id": "57621454-bf58-43ca-94c1-e9b2e257af99", "response_time": 0.033998966217041016, "error": "404: Item not found", "message": "Unhandled Exception", "stack_trace": "Traceback (most recent call last):\n  File \"c:\\users\\jamie\\pycharmprojects\\fastapitest\\venv\\lib\\site-packages\\starlette\\_exception_handler.py\", line 42, in wrapped_app\n    await app(scope, receive, sender)\n  File \"c:\\users\\jamie\\pycharmprojects\\fastapitest\\venv\\lib\\site-packages\\starlette\\routing.py\", line 73, in app\n    response = await f(request)\n  File \"c:\\users\\jamie\\pycharmprojects\\fastapitest\\venv\\lib\\site-packages\\fastapi\\routing.py\", line 301, in app\n    raw_response = await run_endpoint_function(\n  File \"c:\\users\\jamie\\pycharmprojects\\fastapitest\\venv\\lib\\site-packages\\fastapi\\routing.py\", line 212, in run_endpoint_function\n    return await dependant.call(**values)\n  File \"C:\\Users\\Jamie\\PycharmProjects\\fastapitest\\main.py\", line 115, in http\n    raise HTTPException(status_code=404, detail=\"Item not found\")\nfastapi.exceptions.HTTPException: 404: Item not found\n", "logger": "error_logger"}
{"timestamp": "2025-05-08T17:57:30.953171+00:00", "level": "ERROR", "correlation_id": "7564a62b-ffc1-4797-aecf-f8785a577bf8", "response_time": 0.003000974655151367, "error": "404: Item not found", "message": "Unhandled Exception", "stack_trace": "Traceback (most recent call last):\n  File \"c:\\users\\jamie\\pycharmprojects\\fastapitest\\venv\\lib\\site-packages\\starlette\\_exception_handler.py\", line 42, in wrapped_app\n    await app(scope, receive, sender)\n  File \"c:\\users\\jamie\\pycharmprojects\\fastapitest\\venv\\lib\\site-packages\\starlette\\routing.py\", line 73, in app\n    response = await f(request)\n  File \"c:\\users\\jamie\\pycharmprojects\\fastapitest\\venv\\lib\\site-packages\\fastapi\\routing.py\", line 301, in app\n    raw_response = await run_endpoint_function(\n  File \"c:\\users\\jamie\\pycharmprojects\\fastapitest\\venv\\lib\\site-packages\\fastapi\\routing.py\", line 212, in run_endpoint_function\n    return await dependant.call(**values)\n  File \"C:\\Users\\Jamie\\PycharmProjects\\fastapitest\\main.py\", line 117, in http\n    raise HTTPException(status_code=404, detail=\"Item not found\")\nfastapi.exceptions.HTTPException: 404: Item not found\n", "logger": "error_logger"}
{"timestamp": "2025-05-08T18:01:12.352119+00:00", "level": "ERROR", "correlation_id": "19ea3465-ac77-4f8e-aeb1-bb8e69ef7bb9", "response_time": 0.04849958419799805, "error": "local variable 'response' referenced before assignment", "message": "Unhandled Exception", "stack_trace": "  + Exception Group Traceback (most recent call last):\n  |   File \"c:\\users\\jamie\\pycharmprojects\\fastapitest\\venv\\lib\\site-packages\\starlette\\_utils.py\", line 76, in collapse_excgroups\n  |     yield\n  |   File \"c:\\users\\jamie\\pycharmprojects\\fastapitest\\venv\\lib\\site-packages\\starlette\\middleware\\base.py\", line 177, in __call__\n  |     async with anyio.create_task_group() as task_group:\n  |   File \"c:\\users\\jamie\\pycharmprojects\\fastapitest\\venv\\lib\\site-packages\\anyio\\_backends\\_asyncio.py\", line 772, in __aexit__\n  |     raise BaseExceptionGroup(\n  | exceptiongroup.ExceptionGroup: unhandled errors in a TaskGroup (1 sub-exception)\n  +-+---------------- 1 ----------------\n    | Traceback (most recent call last):\n    |   File \"c:\\users\\jamie\\pycharmprojects\\fastapitest\\venv\\lib\\site-packages\\starlette\\middleware\\errors.py\", line 165, in __call__\n    |     await self.app(scope, receive, _send)\n    |   File \"c:\\users\\jamie\\pycharmprojects\\fastapitest\\venv\\lib\\site-packages\\starlette\\middleware\\base.py\", line 176, in __call__\n    |     with recv_stream, send_stream, collapse_excgroups():\n    |   File \"C:\\Program Files\\Python310\\lib\\contextlib.py\", line 153, in __exit__\n    |     self.gen.throw(typ, value, traceback)\n    |   File \"c:\\users\\jamie\\pycharmprojects\\fastapitest\\venv\\lib\\site-packages\\starlette\\_utils.py\", line 82, in collapse_excgroups\n    |     raise exc\n    |   File \"c:\\users\\jamie\\pycharmprojects\\fastapitest\\venv\\lib\\site-packages\\starlette\\middleware\\base.py\", line 178, in __call__\n    |     response = await self.dispatch_func(request, call_next)\n    |   File \"C:\\Users\\Jamie\\PycharmProjects\\fastapitest\\main.py\", line 44, in dispatch\n    |     \"status_code\": response.status_code,\n    | UnboundLocalError: local variable 'response' referenced before assignment\n    +------------------------------------\n\nDuring handling of the above exception, another exception occurred:\n\nTraceback (most recent call last):\n  File \"c:\\users\\jamie\\pycharmprojects\\fastapitest\\venv\\lib\\site-packages\\starlette\\middleware\\errors.py\", line 165, in __call__\n    await self.app(scope, receive, _send)\n  File \"c:\\users\\jamie\\pycharmprojects\\fastapitest\\venv\\lib\\site-packages\\starlette\\middleware\\base.py\", line 176, in __call__\n    with recv_stream, send_stream, collapse_excgroups():\n  File \"C:\\Program Files\\Python310\\lib\\contextlib.py\", line 153, in __exit__\n    self.gen.throw(typ, value, traceback)\n  File \"c:\\users\\jamie\\pycharmprojects\\fastapitest\\venv\\lib\\site-packages\\starlette\\_utils.py\", line 82, in collapse_excgroups\n    raise exc\n  File \"c:\\users\\jamie\\pycharmprojects\\fastapitest\\venv\\lib\\site-packages\\starlette\\middleware\\base.py\", line 178, in __call__\n    response = await self.dispatch_func(request, call_next)\n  File \"C:\\Users\\Jamie\\PycharmProjects\\fastapitest\\main.py\", line 44, in dispatch\n    \"status_code\": response.status_code,\nUnboundLocalError: local variable 'response' referenced before assignment\n", "logger": "error_logger"}
{"timestamp": "2025-05-08T18:02:25.053307+00:00", "level": "ERROR", "correlation_id": "372ca8d8-6f7c-4e6f-97a2-71a8bb7e81b7", "response_time": 0.005002260208129883, "error": "'NoneType' object has no attribute 'status_code'", "message": "Unhandled Exception", "stack_trace": "  + Exception Group Traceback (most recent call last):\n  |   File \"c:\\users\\jamie\\pycharmprojects\\fastapitest\\venv\\lib\\site-packages\\starlette\\_utils.py\", line 76, in collapse_excgroups\n  |     yield\n  |   File \"c:\\users\\jamie\\pycharmprojects\\fastapitest\\venv\\lib\\site-packages\\starlette\\middleware\\base.py\", line 177, in __call__\n  |     async with anyio.create_task_group() as task_group:\n  |   File \"c:\\users\\jamie\\pycharmprojects\\fastapitest\\venv\\lib\\site-packages\\anyio\\_backends\\_asyncio.py\", line 772, in __aexit__\n  |     raise BaseExceptionGroup(\n  | exceptiongroup.ExceptionGroup: unhandled errors in a TaskGroup (1 sub-exception)\n  +-+---------------- 1 ----------------\n    | Traceback (most recent call last):\n    |   File \"c:\\users\\jamie\\pycharmprojects\\fastapitest\\venv\\lib\\site-packages\\starlette\\middleware\\errors.py\", line 165, in __call__\n    |     await self.app(scope, receive, _send)\n    |   File \"c:\\users\\jamie\\pycharmprojects\\fastapitest\\venv\\lib\\site-packages\\starlette\\middleware\\base.py\", line 176, in __call__\n    |     with recv_stream, send_stream, collapse_excgroups():\n    |   File \"C:\\Program Files\\Python310\\lib\\contextlib.py\", line 153, in __exit__\n    |     self.gen.throw(typ, value, traceback)\n    |   File \"c:\\users\\jamie\\pycharmprojects\\fastapitest\\venv\\lib\\site-packages\\starlette\\_utils.py\", line 82, in collapse_excgroups\n    |     raise exc\n    |   File \"c:\\users\\jamie\\pycharmprojects\\fastapitest\\venv\\lib\\site-packages\\starlette\\middleware\\base.py\", line 178, in __call__\n    |     response = await self.dispatch_func(request, call_next)\n    |   File \"C:\\Users\\Jamie\\PycharmProjects\\fastapitest\\main.py\", line 45, in dispatch\n    |     \"status_code\": response.status_code,\n    | AttributeError: 'NoneType' object has no attribute 'status_code'\n    +------------------------------------\n\nDuring handling of the above exception, another exception occurred:\n\nTraceback (most recent call last):\n  File \"c:\\users\\jamie\\pycharmprojects\\fastapitest\\venv\\lib\\site-packages\\starlette\\middleware\\errors.py\", line 165, in __call__\n    await self.app(scope, receive, _send)\n  File \"c:\\users\\jamie\\pycharmprojects\\fastapitest\\venv\\lib\\site-packages\\starlette\\middleware\\base.py\", line 176, in __call__\n    with recv_stream, send_stream, collapse_excgroups():\n  File \"C:\\Program Files\\Python310\\lib\\contextlib.py\", line 153, in __exit__\n    self.gen.throw(typ, value, traceback)\n  File \"c:\\users\\jamie\\pycharmprojects\\fastapitest\\venv\\lib\\site-packages\\starlette\\_utils.py\", line 82, in collapse_excgroups\n    raise exc\n  File \"c:\\users\\jamie\\pycharmprojects\\fastapitest\\venv\\lib\\site-packages\\starlette\\middleware\\base.py\", line 178, in __call__\n    response = await self.dispatch_func(request, call_next)\n  File \"C:\\Users\\Jamie\\PycharmProjects\\fastapitest\\main.py\", line 45, in dispatch\n    \"status_code\": response.status_code,\nAttributeError: 'NoneType' object has no attribute 'status_code'\n", "logger": "error_logger"}
{"timestamp": "2025-05-08T18:02:41.596436+00:00", "level": "ERROR", "correlation_id": "bd2d8311-7419-4dfd-98a3-920494ac8fe4", "response_time": 0.01599907875061035, "error": "division by zero", "message": "Unhandled Exception", "stack_trace": "  + Exception Group Traceback (most recent call last):\n  |   File \"c:\\users\\jamie\\pycharmprojects\\fastapitest\\venv\\lib\\site-packages\\starlette\\_utils.py\", line 76, in collapse_excgroups\n  |     yield\n  |   File \"c:\\users\\jamie\\pycharmprojects\\fastapitest\\venv\\lib\\site-packages\\starlette\\middleware\\base.py\", line 177, in __call__\n  |     async with anyio.create_task_group() as task_group:\n  |   File \"c:\\users\\jamie\\pycharmprojects\\fastapitest\\venv\\lib\\site-packages\\anyio\\_backends\\_asyncio.py\", line 772, in __aexit__\n  |     raise BaseExceptionGroup(\n  | exceptiongroup.ExceptionGroup: unhandled errors in a TaskGroup (1 sub-exception)\n  +-+---------------- 1 ----------------\n    | Traceback (most recent call last):\n    |   File \"c:\\users\\jamie\\pycharmprojects\\fastapitest\\venv\\lib\\site-packages\\starlette\\middleware\\errors.py\", line 165, in __call__\n    |     await self.app(scope, receive, _send)\n    |   File \"c:\\users\\jamie\\pycharmprojects\\fastapitest\\venv\\lib\\site-packages\\starlette\\middleware\\base.py\", line 176, in __call__\n    |     with recv_stream, send_stream, collapse_excgroups():\n    |   File \"C:\\Program Files\\Python310\\lib\\contextlib.py\", line 153, in __exit__\n    |     self.gen.throw(typ, value, traceback)\n    |   File \"c:\\users\\jamie\\pycharmprojects\\fastapitest\\venv\\lib\\site-packages\\starlette\\_utils.py\", line 82, in collapse_excgroups\n    |     raise exc\n    |   File \"c:\\users\\jamie\\pycharmprojects\\fastapitest\\venv\\lib\\site-packages\\starlette\\middleware\\base.py\", line 178, in __call__\n    |     response = await self.dispatch_func(request, call_next)\n    |   File \"C:\\Users\\Jamie\\PycharmProjects\\fastapitest\\main.py\", line 32, in dispatch\n    |     response = await call_next(request)\n    |   File \"c:\\users\\jamie\\pycharmprojects\\fastapitest\\venv\\lib\\site-packages\\starlette\\middleware\\base.py\", line 156, in call_next\n    |     raise app_exc\n    |   File \"c:\\users\\jamie\\pycharmprojects\\fastapitest\\venv\\lib\\site-packages\\starlette\\middleware\\base.py\", line 141, in coro\n    |     await self.app(scope, receive_or_disconnect, send_no_error)\n    |   File \"c:\\users\\jamie\\pycharmprojects\\fastapitest\\venv\\lib\\site-packages\\starlette\\middleware\\exceptions.py\", line 62, in __call__\n    |     await wrap_app_handling_exceptions(self.app, conn)(scope, receive, send)\n    |   File \"c:\\users\\jamie\\pycharmprojects\\fastapitest\\venv\\lib\\site-packages\\starlette\\_exception_handler.py\", line 53, in wrapped_app\n    |     raise exc\n    |   File \"c:\\users\\jamie\\pycharmprojects\\fastapitest\\venv\\lib\\site-packages\\starlette\\_exception_handler.py\", line 42, in wrapped_app\n    |     await app(scope, receive, sender)\n    |   File \"c:\\users\\jamie\\pycharmprojects\\fastapitest\\venv\\lib\\site-packages\\starlette\\routing.py\", line 714, in __call__\n    |     await self.middleware_stack(scope, receive, send)\n    |   File \"c:\\users\\jamie\\pycharmprojects\\fastapitest\\venv\\lib\\site-packages\\starlette\\routing.py\", line 734, in app\n    |     await route.handle(scope, receive, send)\n    |   File \"c:\\users\\jamie\\pycharmprojects\\fastapitest\\venv\\lib\\site-packages\\starlette\\routing.py\", line 288, in handle\n    |     await self.app(scope, receive, send)\n    |   File \"c:\\users\\jamie\\pycharmprojects\\fastapitest\\venv\\lib\\site-packages\\starlette\\routing.py\", line 76, in app\n    |     await wrap_app_handling_exceptions(app, request)(scope, receive, send)\n    |   File \"c:\\users\\jamie\\pycharmprojects\\fastapitest\\venv\\lib\\site-packages\\starlette\\_exception_handler.py\", line 53, in wrapped_app\n    |     raise exc\n    |   File \"c:\\users\\jamie\\pycharmprojects\\fastapitest\\venv\\lib\\site-packages\\starlette\\_exception_handler.py\", line 42, in wrapped_app\n    |     await app(scope, receive, sender)\n    |   File \"c:\\users\\jamie\\pycharmprojects\\fastapitest\\venv\\lib\\site-packages\\starlette\\routing.py\", line 73, in app\n    |     response = await f(request)\n    |   File \"c:\\users\\jamie\\pycharmprojects\\fastapitest\\venv\\lib\\site-packages\\fastapi\\routing.py\", line 301, in app\n    |     raw_response = await run_endpoint_function(\n    |   File \"c:\\users\\jamie\\pycharmprojects\\fastapitest\\venv\\lib\\site-packages\\fastapi\\routing.py\", line 212, in run_endpoint_function\n    |     return await dependant.call(**values)\n    |   File \"C:\\Users\\Jamie\\PycharmProjects\\fastapitest\\main.py\", line 106, in error\n    |     _ = 1 / 0  # Force an error to test logging\n    | ZeroDivisionError: division by zero\n    +------------------------------------\n\nDuring handling of the above exception, another exception occurred:\n\nTraceback (most recent call last):\n  File \"c:\\users\\jamie\\pycharmprojects\\fastapitest\\venv\\lib\\site-packages\\starlette\\middleware\\errors.py\", line 165, in __call__\n    await self.app(scope, receive, _send)\n  File \"c:\\users\\jamie\\pycharmprojects\\fastapitest\\venv\\lib\\site-packages\\starlette\\middleware\\base.py\", line 176, in __call__\n    with recv_stream, send_stream, collapse_excgroups():\n  File \"C:\\Program Files\\Python310\\lib\\contextlib.py\", line 153, in __exit__\n    self.gen.throw(typ, value, traceback)\n  File \"c:\\users\\jamie\\pycharmprojects\\fastapitest\\venv\\lib\\site-packages\\starlette\\_utils.py\", line 82, in collapse_excgroups\n    raise exc\n  File \"c:\\users\\jamie\\pycharmprojects\\fastapitest\\venv\\lib\\site-packages\\starlette\\middleware\\base.py\", line 178, in __call__\n    response = await self.dispatch_func(request, call_next)\n  File \"C:\\Users\\Jamie\\PycharmProjects\\fastapitest\\main.py\", line 32, in dispatch\n    response = await call_next(request)\n  File \"c:\\users\\jamie\\pycharmprojects\\fastapitest\\venv\\lib\\site-packages\\starlette\\middleware\\base.py\", line 156, in call_next\n    raise app_exc\n  File \"c:\\users\\jamie\\pycharmprojects\\fastapitest\\venv\\lib\\site-packages\\starlette\\middleware\\base.py\", line 141, in coro\n    await self.app(scope, receive_or_disconnect, send_no_error)\n  File \"c:\\users\\jamie\\pycharmprojects\\fastapitest\\venv\\lib\\site-packages\\starlette\\middleware\\exceptions.py\", line 62, in __call__\n    await wrap_app_handling_exceptions(self.app, conn)(scope, receive, send)\n  File \"c:\\users\\jamie\\pycharmprojects\\fastapitest\\venv\\lib\\site-packages\\starlette\\_exception_handler.py\", line 53, in wrapped_app\n    raise exc\n  File \"c:\\users\\jamie\\pycharmprojects\\fastapitest\\venv\\lib\\site-packages\\starlette\\_exception_handler.py\", line 42, in wrapped_app\n    await app(scope, receive, sender)\n  File \"c:\\users\\jamie\\pycharmprojects\\fastapitest\\venv\\lib\\site-packages\\starlette\\routing.py\", line 714, in __call__\n    await self.middleware_stack(scope, receive, send)\n  File \"c:\\users\\jamie\\pycharmprojects\\fastapitest\\venv\\lib\\site-packages\\starlette\\routing.py\", line 734, in app\n    await route.handle(scope, receive, send)\n  File \"c:\\users\\jamie\\pycharmprojects\\fastapitest\\venv\\lib\\site-packages\\starlette\\routing.py\", line 288, in handle\n    await self.app(scope, receive, send)\n  File \"c:\\users\\jamie\\pycharmprojects\\fastapitest\\venv\\lib\\site-packages\\starlette\\routing.py\", line 76, in app\n    await wrap_app_handling_exceptions(app, request)(scope, receive, send)\n  File \"c:\\users\\jamie\\pycharmprojects\\fastapitest\\venv\\lib\\site-packages\\starlette\\_exception_handler.py\", line 53, in wrapped_app\n    raise exc\n  File \"c:\\users\\jamie\\pycharmprojects\\fastapitest\\venv\\lib\\site-packages\\starlette\\_exception_handler.py\", line 42, in wrapped_app\n    await app(scope, receive, sender)\n  File \"c:\\users\\jamie\\pycharmprojects\\fastapitest\\venv\\lib\\site-packages\\starlette\\routing.py\", line 73, in app\n    response = await f(request)\n  File \"c:\\users\\jamie\\pycharmprojects\\fastapitest\\venv\\lib\\site-packages\\fastapi\\routing.py\", line 301, in app\n    raw_response = await run_endpoint_function(\n  File \"c:\\users\\jamie\\pycharmprojects\\fastapitest\\venv\\lib\\site-packages\\fastapi\\routing.py\", line 212, in run_endpoint_function\n    return await dependant.call(**values)\n  File \"C:\\Users\\Jamie\\PycharmProjects\\fastapitest\\main.py\", line 106, in error\n    _ = 1 / 0  # Force an error to test logging\nZeroDivisionError: division by zero\n", "logger": "error_logger"}
{"timestamp": "2025-05-08T18:03:13.076353+00:00", "level": "ERROR", "correlation_id": "98903744-3550-497c-9471-c832a7713277", "response_time": 0.0024979114532470703, "error": "division by zero", "message": "Unhandled Exception", "stack_trace": "  + Exception Group Traceback (most recent call last):\n  |   File \"c:\\users\\jamie\\pycharmprojects\\fastapitest\\venv\\lib\\site-packages\\starlette\\_utils.py\", line 76, in collapse_excgroups\n  |     yield\n  |   File \"c:\\users\\jamie\\pycharmprojects\\fastapitest\\venv\\lib\\site-packages\\starlette\\middleware\\base.py\", line 177, in __call__\n  |     async with anyio.create_task_group() as task_group:\n  |   File \"c:\\users\\jamie\\pycharmprojects\\fastapitest\\venv\\lib\\site-packages\\anyio\\_backends\\_asyncio.py\", line 772, in __aexit__\n  |     raise BaseExceptionGroup(\n  | exceptiongroup.ExceptionGroup: unhandled errors in a TaskGroup (1 sub-exception)\n  +-+---------------- 1 ----------------\n    | Traceback (most recent call last):\n    |   File \"c:\\users\\jamie\\pycharmprojects\\fastapitest\\venv\\lib\\site-packages\\starlette\\middleware\\errors.py\", line 165, in __call__\n    |     await self.app(scope, receive, _send)\n    |   File \"c:\\users\\jamie\\pycharmprojects\\fastapitest\\venv\\lib\\site-packages\\starlette\\middleware\\base.py\", line 176, in __call__\n    |     with recv_stream, send_stream, collapse_excgroups():\n    |   File \"C:\\Program Files\\Python310\\lib\\contextlib.py\", line 153, in __exit__\n    |     self.gen.throw(typ, value, traceback)\n    |   File \"c:\\users\\jamie\\pycharmprojects\\fastapitest\\venv\\lib\\site-packages\\starlette\\_utils.py\", line 82, in collapse_excgroups\n    |     raise exc\n    |   File \"c:\\users\\jamie\\pycharmprojects\\fastapitest\\venv\\lib\\site-packages\\starlette\\middleware\\base.py\", line 178, in __call__\n    |     response = await self.dispatch_func(request, call_next)\n    |   File \"C:\\Users\\Jamie\\PycharmProjects\\fastapitest\\main.py\", line 32, in dispatch\n    |     response = await call_next(request)\n    |   File \"c:\\users\\jamie\\pycharmprojects\\fastapitest\\venv\\lib\\site-packages\\starlette\\middleware\\base.py\", line 156, in call_next\n    |     raise app_exc\n    |   File \"c:\\users\\jamie\\pycharmprojects\\fastapitest\\venv\\lib\\site-packages\\starlette\\middleware\\base.py\", line 141, in coro\n    |     await self.app(scope, receive_or_disconnect, send_no_error)\n    |   File \"c:\\users\\jamie\\pycharmprojects\\fastapitest\\venv\\lib\\site-packages\\starlette\\middleware\\exceptions.py\", line 62, in __call__\n    |     await wrap_app_handling_exceptions(self.app, conn)(scope, receive, send)\n    |   File \"c:\\users\\jamie\\pycharmprojects\\fastapitest\\venv\\lib\\site-packages\\starlette\\_exception_handler.py\", line 53, in wrapped_app\n    |     raise exc\n    |   File \"c:\\users\\jamie\\pycharmprojects\\fastapitest\\venv\\lib\\site-packages\\starlette\\_exception_handler.py\", line 42, in wrapped_app\n    |     await app(scope, receive, sender)\n    |   File \"c:\\users\\jamie\\pycharmprojects\\fastapitest\\venv\\lib\\site-packages\\starlette\\routing.py\", line 714, in __call__\n    |     await self.middleware_stack(scope, receive, send)\n    |   File \"c:\\users\\jamie\\pycharmprojects\\fastapitest\\venv\\lib\\site-packages\\starlette\\routing.py\", line 734, in app\n    |     await route.handle(scope, receive, send)\n    |   File \"c:\\users\\jamie\\pycharmprojects\\fastapitest\\venv\\lib\\site-packages\\starlette\\routing.py\", line 288, in handle\n    |     await self.app(scope, receive, send)\n    |   File \"c:\\users\\jamie\\pycharmprojects\\fastapitest\\venv\\lib\\site-packages\\starlette\\routing.py\", line 76, in app\n    |     await wrap_app_handling_exceptions(app, request)(scope, receive, send)\n    |   File \"c:\\users\\jamie\\pycharmprojects\\fastapitest\\venv\\lib\\site-packages\\starlette\\_exception_handler.py\", line 53, in wrapped_app\n    |     raise exc\n    |   File \"c:\\users\\jamie\\pycharmprojects\\fastapitest\\venv\\lib\\site-packages\\starlette\\_exception_handler.py\", line 42, in wrapped_app\n    |     await app(scope, receive, sender)\n    |   File \"c:\\users\\jamie\\pycharmprojects\\fastapitest\\venv\\lib\\site-packages\\starlette\\routing.py\", line 73, in app\n    |     response = await f(request)\n    |   File \"c:\\users\\jamie\\pycharmprojects\\fastapitest\\venv\\lib\\site-packages\\fastapi\\routing.py\", line 301, in app\n    |     raw_response = await run_endpoint_function(\n    |   File \"c:\\users\\jamie\\pycharmprojects\\fastapitest\\venv\\lib\\site-packages\\fastapi\\routing.py\", line 212, in run_endpoint_function\n    |     return await dependant.call(**values)\n    |   File \"C:\\Users\\Jamie\\PycharmProjects\\fastapitest\\main.py\", line 106, in error\n    |     _ = 1 / 0  # Force an error to test logging\n    | ZeroDivisionError: division by zero\n    +------------------------------------\n\nDuring handling of the above exception, another exception occurred:\n\nTraceback (most recent call last):\n  File \"c:\\users\\jamie\\pycharmprojects\\fastapitest\\venv\\lib\\site-packages\\starlette\\middleware\\errors.py\", line 165, in __call__\n    await self.app(scope, receive, _send)\n  File \"c:\\users\\jamie\\pycharmprojects\\fastapitest\\venv\\lib\\site-packages\\starlette\\middleware\\base.py\", line 176, in __call__\n    with recv_stream, send_stream, collapse_excgroups():\n  File \"C:\\Program Files\\Python310\\lib\\contextlib.py\", line 153, in __exit__\n    self.gen.throw(typ, value, traceback)\n  File \"c:\\users\\jamie\\pycharmprojects\\fastapitest\\venv\\lib\\site-packages\\starlette\\_utils.py\", line 82, in collapse_excgroups\n    raise exc\n  File \"c:\\users\\jamie\\pycharmprojects\\fastapitest\\venv\\lib\\site-packages\\starlette\\middleware\\base.py\", line 178, in __call__\n    response = await self.dispatch_func(request, call_next)\n  File \"C:\\Users\\Jamie\\PycharmProjects\\fastapitest\\main.py\", line 32, in dispatch\n    response = await call_next(request)\n  File \"c:\\users\\jamie\\pycharmprojects\\fastapitest\\venv\\lib\\site-packages\\starlette\\middleware\\base.py\", line 156, in call_next\n    raise app_exc\n  File \"c:\\users\\jamie\\pycharmprojects\\fastapitest\\venv\\lib\\site-packages\\starlette\\middleware\\base.py\", line 141, in coro\n    await self.app(scope, receive_or_disconnect, send_no_error)\n  File \"c:\\users\\jamie\\pycharmprojects\\fastapitest\\venv\\lib\\site-packages\\starlette\\middleware\\exceptions.py\", line 62, in __call__\n    await wrap_app_handling_exceptions(self.app, conn)(scope, receive, send)\n  File \"c:\\users\\jamie\\pycharmprojects\\fastapitest\\venv\\lib\\site-packages\\starlette\\_exception_handler.py\", line 53, in wrapped_app\n    raise exc\n  File \"c:\\users\\jamie\\pycharmprojects\\fastapitest\\venv\\lib\\site-packages\\starlette\\_exception_handler.py\", line 42, in wrapped_app\n    await app(scope, receive, sender)\n  File \"c:\\users\\jamie\\pycharmprojects\\fastapitest\\venv\\lib\\site-packages\\starlette\\routing.py\", line 714, in __call__\n    await self.middleware_stack(scope, receive, send)\n  File \"c:\\users\\jamie\\pycharmprojects\\fastapitest\\venv\\lib\\site-packages\\starlette\\routing.py\", line 734, in app\n    await route.handle(scope, receive, send)\n  File \"c:\\users\\jamie\\pycharmprojects\\fastapitest\\venv\\lib\\site-packages\\starlette\\routing.py\", line 288, in handle\n    await self.app(scope, receive, send)\n  File \"c:\\users\\jamie\\pycharmprojects\\fastapitest\\venv\\lib\\site-packages\\starlette\\routing.py\", line 76, in app\n    await wrap_app_handling_exceptions(app, request)(scope, receive, send)\n  File \"c:\\users\\jamie\\pycharmprojects\\fastapitest\\venv\\lib\\site-packages\\starlette\\_exception_handler.py\", line 53, in wrapped_app\n    raise exc\n  File \"c:\\users\\jamie\\pycharmprojects\\fastapitest\\venv\\lib\\site-packages\\starlette\\_exception_handler.py\", line 42, in wrapped_app\n    await app(scope, receive, sender)\n  File \"c:\\users\\jamie\\pycharmprojects\\fastapitest\\venv\\lib\\site-packages\\starlette\\routing.py\", line 73, in app\n    response = await f(request)\n  File \"c:\\users\\jamie\\pycharmprojects\\fastapitest\\venv\\lib\\site-packages\\fastapi\\routing.py\", line 301, in app\n    raw_response = await run_endpoint_function(\n  File \"c:\\users\\jamie\\pycharmprojects\\fastapitest\\venv\\lib\\site-packages\\fastapi\\routing.py\", line 212, in run_endpoint_function\n    return await dependant.call(**values)\n  File \"C:\\Users\\Jamie\\PycharmProjects\\fastapitest\\main.py\", line 106, in error\n    _ = 1 / 0  # Force an error to test logging\nZeroDivisionError: division by zero\n", "logger": "error_logger"}
{"timestamp": "2025-05-08T18:03:24.655060+00:00", "level": "ERROR", "correlation_id": "463eb920-5fa4-4306-b3cc-4e11051959a1", "response_time": 0.0010013580322265625, "error": "404: Item not found", "message": "Unhandled Exception", "stack_trace": "Traceback (most recent call last):\n  File \"c:\\users\\jamie\\pycharmprojects\\fastapitest\\venv\\lib\\site-packages\\starlette\\_exception_handler.py\", line 42, in wrapped_app\n    await app(scope, receive, sender)\n  File \"c:\\users\\jamie\\pycharmprojects\\fastapitest\\venv\\lib\\site-packages\\starlette\\routing.py\", line 73, in app\n    response = await f(request)\n  File \"c:\\users\\jamie\\pycharmprojects\\fastapitest\\venv\\lib\\site-packages\\fastapi\\routing.py\", line 301, in app\n    raw_response = await run_endpoint_function(\n  File \"c:\\users\\jamie\\pycharmprojects\\fastapitest\\venv\\lib\\site-packages\\fastapi\\routing.py\", line 212, in run_endpoint_function\n    return await dependant.call(**values)\n  File \"C:\\Users\\Jamie\\PycharmProjects\\fastapitest\\main.py\", line 120, in http\n    raise HTTPException(status_code=404, detail=\"Item not found\")\nfastapi.exceptions.HTTPException: 404: Item not found\n", "logger": "error_logger"}
{"timestamp": "2025-05-08T18:05:30.123628+00:00", "level": "ERROR", "correlation_id": "f54b754c-e464-4f7c-b37f-9656bf0e30d2", "response_time": 0.007000446319580078, "error": "ValueError() takes no keyword arguments", "message": "Unhandled Exception", "stack_trace": "  + Exception Group Traceback (most recent call last):\n  |   File \"c:\\users\\jamie\\pycharmprojects\\fastapitest\\venv\\lib\\site-packages\\starlette\\_utils.py\", line 76, in collapse_excgroups\n  |     yield\n  |   File \"c:\\users\\jamie\\pycharmprojects\\fastapitest\\venv\\lib\\site-packages\\starlette\\middleware\\base.py\", line 177, in __call__\n  |     async with anyio.create_task_group() as task_group:\n  |   File \"c:\\users\\jamie\\pycharmprojects\\fastapitest\\venv\\lib\\site-packages\\anyio\\_backends\\_asyncio.py\", line 772, in __aexit__\n  |     raise BaseExceptionGroup(\n  | exceptiongroup.ExceptionGroup: unhandled errors in a TaskGroup (1 sub-exception)\n  +-+---------------- 1 ----------------\n    | Traceback (most recent call last):\n    |   File \"c:\\users\\jamie\\pycharmprojects\\fastapitest\\venv\\lib\\site-packages\\starlette\\middleware\\errors.py\", line 165, in __call__\n    |     await self.app(scope, receive, _send)\n    |   File \"c:\\users\\jamie\\pycharmprojects\\fastapitest\\venv\\lib\\site-packages\\starlette\\middleware\\base.py\", line 176, in __call__\n    |     with recv_stream, send_stream, collapse_excgroups():\n    |   File \"C:\\Program Files\\Python310\\lib\\contextlib.py\", line 153, in __exit__\n    |     self.gen.throw(typ, value, traceback)\n    |   File \"c:\\users\\jamie\\pycharmprojects\\fastapitest\\venv\\lib\\site-packages\\starlette\\_utils.py\", line 82, in collapse_excgroups\n    |     raise exc\n    |   File \"c:\\users\\jamie\\pycharmprojects\\fastapitest\\venv\\lib\\site-packages\\starlette\\middleware\\base.py\", line 178, in __call__\n    |     response = await self.dispatch_func(request, call_next)\n    |   File \"C:\\Users\\Jamie\\PycharmProjects\\fastapitest\\main.py\", line 30, in dispatch\n    |     response = await call_next(request)\n    |   File \"c:\\users\\jamie\\pycharmprojects\\fastapitest\\venv\\lib\\site-packages\\starlette\\middleware\\base.py\", line 156, in call_next\n    |     raise app_exc\n    |   File \"c:\\users\\jamie\\pycharmprojects\\fastapitest\\venv\\lib\\site-packages\\starlette\\middleware\\base.py\", line 141, in coro\n    |     await self.app(scope, receive_or_disconnect, send_no_error)\n    |   File \"c:\\users\\jamie\\pycharmprojects\\fastapitest\\venv\\lib\\site-packages\\starlette\\middleware\\exceptions.py\", line 62, in __call__\n    |     await wrap_app_handling_exceptions(self.app, conn)(scope, receive, send)\n    |   File \"c:\\users\\jamie\\pycharmprojects\\fastapitest\\venv\\lib\\site-packages\\starlette\\_exception_handler.py\", line 53, in wrapped_app\n    |     raise exc\n    |   File \"c:\\users\\jamie\\pycharmprojects\\fastapitest\\venv\\lib\\site-packages\\starlette\\_exception_handler.py\", line 42, in wrapped_app\n    |     await app(scope, receive, sender)\n    |   File \"c:\\users\\jamie\\pycharmprojects\\fastapitest\\venv\\lib\\site-packages\\starlette\\routing.py\", line 714, in __call__\n    |     await self.middleware_stack(scope, receive, send)\n    |   File \"c:\\users\\jamie\\pycharmprojects\\fastapitest\\venv\\lib\\site-packages\\starlette\\routing.py\", line 734, in app\n    |     await route.handle(scope, receive, send)\n    |   File \"c:\\users\\jamie\\pycharmprojects\\fastapitest\\venv\\lib\\site-packages\\starlette\\routing.py\", line 288, in handle\n    |     await self.app(scope, receive, send)\n    |   File \"c:\\users\\jamie\\pycharmprojects\\fastapitest\\venv\\lib\\site-packages\\starlette\\routing.py\", line 76, in app\n    |     await wrap_app_handling_exceptions(app, request)(scope, receive, send)\n    |   File \"c:\\users\\jamie\\pycharmprojects\\fastapitest\\venv\\lib\\site-packages\\starlette\\_exception_handler.py\", line 53, in wrapped_app\n    |     raise exc\n    |   File \"c:\\users\\jamie\\pycharmprojects\\fastapitest\\venv\\lib\\site-packages\\starlette\\_exception_handler.py\", line 42, in wrapped_app\n    |     await app(scope, receive, sender)\n    |   File \"c:\\users\\jamie\\pycharmprojects\\fastapitest\\venv\\lib\\site-packages\\starlette\\routing.py\", line 73, in app\n    |     response = await f(request)\n    |   File \"c:\\users\\jamie\\pycharmprojects\\fastapitest\\venv\\lib\\site-packages\\fastapi\\routing.py\", line 301, in app\n    |     raw_response = await run_endpoint_function(\n    |   File \"c:\\users\\jamie\\pycharmprojects\\fastapitest\\venv\\lib\\site-packages\\fastapi\\routing.py\", line 212, in run_endpoint_function\n    |     return await dependant.call(**values)\n    |   File \"C:\\Users\\Jamie\\PycharmProjects\\fastapitest\\main.py\", line 119, in http\n    |     raise ValueError(status_code=404, detail=\"Item not found\")\n    | TypeError: ValueError() takes no keyword arguments\n    +------------------------------------\n\nDuring handling of the above exception, another exception occurred:\n\nTraceback (most recent call last):\n  File \"c:\\users\\jamie\\pycharmprojects\\fastapitest\\venv\\lib\\site-packages\\starlette\\middleware\\errors.py\", line 165, in __call__\n    await self.app(scope, receive, _send)\n  File \"c:\\users\\jamie\\pycharmprojects\\fastapitest\\venv\\lib\\site-packages\\starlette\\middleware\\base.py\", line 176, in __call__\n    with recv_stream, send_stream, collapse_excgroups():\n  File \"C:\\Program Files\\Python310\\lib\\contextlib.py\", line 153, in __exit__\n    self.gen.throw(typ, value, traceback)\n  File \"c:\\users\\jamie\\pycharmprojects\\fastapitest\\venv\\lib\\site-packages\\starlette\\_utils.py\", line 82, in collapse_excgroups\n    raise exc\n  File \"c:\\users\\jamie\\pycharmprojects\\fastapitest\\venv\\lib\\site-packages\\starlette\\middleware\\base.py\", line 178, in __call__\n    response = await self.dispatch_func(request, call_next)\n  File \"C:\\Users\\Jamie\\PycharmProjects\\fastapitest\\main.py\", line 30, in dispatch\n    response = await call_next(request)\n  File \"c:\\users\\jamie\\pycharmprojects\\fastapitest\\venv\\lib\\site-packages\\starlette\\middleware\\base.py\", line 156, in call_next\n    raise app_exc\n  File \"c:\\users\\jamie\\pycharmprojects\\fastapitest\\venv\\lib\\site-packages\\starlette\\middleware\\base.py\", line 141, in coro\n    await self.app(scope, receive_or_disconnect, send_no_error)\n  File \"c:\\users\\jamie\\pycharmprojects\\fastapitest\\venv\\lib\\site-packages\\starlette\\middleware\\exceptions.py\", line 62, in __call__\n    await wrap_app_handling_exceptions(self.app, conn)(scope, receive, send)\n  File \"c:\\users\\jamie\\pycharmprojects\\fastapitest\\venv\\lib\\site-packages\\starlette\\_exception_handler.py\", line 53, in wrapped_app\n    raise exc\n  File \"c:\\users\\jamie\\pycharmprojects\\fastapitest\\venv\\lib\\site-packages\\starlette\\_exception_handler.py\", line 42, in wrapped_app\n    await app(scope, receive, sender)\n  File \"c:\\users\\jamie\\pycharmprojects\\fastapitest\\venv\\lib\\site-packages\\starlette\\routing.py\", line 714, in __call__\n    await self.middleware_stack(scope, receive, send)\n  File \"c:\\users\\jamie\\pycharmprojects\\fastapitest\\venv\\lib\\site-packages\\starlette\\routing.py\", line 734, in app\n    await route.handle(scope, receive, send)\n  File \"c:\\users\\jamie\\pycharmprojects\\fastapitest\\venv\\lib\\site-packages\\starlette\\routing.py\", line 288, in handle\n    await self.app(scope, receive, send)\n  File \"c:\\users\\jamie\\pycharmprojects\\fastapitest\\venv\\lib\\site-packages\\starlette\\routing.py\", line 76, in app\n    await wrap_app_handling_exceptions(app, request)(scope, receive, send)\n  File \"c:\\users\\jamie\\pycharmprojects\\fastapitest\\venv\\lib\\site-packages\\starlette\\_exception_handler.py\", line 53, in wrapped_app\n    raise exc\n  File \"c:\\users\\jamie\\pycharmprojects\\fastapitest\\venv\\lib\\site-packages\\starlette\\_exception_handler.py\", line 42, in wrapped_app\n    await app(scope, receive, sender)\n  File \"c:\\users\\jamie\\pycharmprojects\\fastapitest\\venv\\lib\\site-packages\\starlette\\routing.py\", line 73, in app\n    response = await f(request)\n  File \"c:\\users\\jamie\\pycharmprojects\\fastapitest\\venv\\lib\\site-packages\\fastapi\\routing.py\", line 301, in app\n    raw_response = await run_endpoint_function(\n  File \"c:\\users\\jamie\\pycharmprojects\\fastapitest\\venv\\lib\\site-packages\\fastapi\\routing.py\", line 212, in run_endpoint_function\n    return await dependant.call(**values)\n  File \"C:\\Users\\Jamie\\PycharmProjects\\fastapitest\\main.py\", line 119, in http\n    raise ValueError(status_code=404, detail=\"Item not found\")\nTypeError: ValueError() takes no keyword arguments\n", "logger": "error_logger"}
{"timestamp": "2025-05-08T18:05:43.294570+00:00", "level": "ERROR", "correlation_id": "304d0ce9-6ddf-47e8-9525-dd8731f03c0f", "response_time": 0.004496574401855469, "error": "Item not found", "message": "Unhandled Exception", "stack_trace": "  + Exception Group Traceback (most recent call last):\n  |   File \"c:\\users\\jamie\\pycharmprojects\\fastapitest\\venv\\lib\\site-packages\\starlette\\_utils.py\", line 76, in collapse_excgroups\n  |     yield\n  |   File \"c:\\users\\jamie\\pycharmprojects\\fastapitest\\venv\\lib\\site-packages\\starlette\\middleware\\base.py\", line 177, in __call__\n  |     async with anyio.create_task_group() as task_group:\n  |   File \"c:\\users\\jamie\\pycharmprojects\\fastapitest\\venv\\lib\\site-packages\\anyio\\_backends\\_asyncio.py\", line 772, in __aexit__\n  |     raise BaseExceptionGroup(\n  | exceptiongroup.ExceptionGroup: unhandled errors in a TaskGroup (1 sub-exception)\n  +-+---------------- 1 ----------------\n    | Traceback (most recent call last):\n    |   File \"c:\\users\\jamie\\pycharmprojects\\fastapitest\\venv\\lib\\site-packages\\starlette\\middleware\\errors.py\", line 165, in __call__\n    |     await self.app(scope, receive, _send)\n    |   File \"c:\\users\\jamie\\pycharmprojects\\fastapitest\\venv\\lib\\site-packages\\starlette\\middleware\\base.py\", line 176, in __call__\n    |     with recv_stream, send_stream, collapse_excgroups():\n    |   File \"C:\\Program Files\\Python310\\lib\\contextlib.py\", line 153, in __exit__\n    |     self.gen.throw(typ, value, traceback)\n    |   File \"c:\\users\\jamie\\pycharmprojects\\fastapitest\\venv\\lib\\site-packages\\starlette\\_utils.py\", line 82, in collapse_excgroups\n    |     raise exc\n    |   File \"c:\\users\\jamie\\pycharmprojects\\fastapitest\\venv\\lib\\site-packages\\starlette\\middleware\\base.py\", line 178, in __call__\n    |     response = await self.dispatch_func(request, call_next)\n    |   File \"C:\\Users\\Jamie\\PycharmProjects\\fastapitest\\main.py\", line 30, in dispatch\n    |     response = await call_next(request)\n    |   File \"c:\\users\\jamie\\pycharmprojects\\fastapitest\\venv\\lib\\site-packages\\starlette\\middleware\\base.py\", line 156, in call_next\n    |     raise app_exc\n    |   File \"c:\\users\\jamie\\pycharmprojects\\fastapitest\\venv\\lib\\site-packages\\starlette\\middleware\\base.py\", line 141, in coro\n    |     await self.app(scope, receive_or_disconnect, send_no_error)\n    |   File \"c:\\users\\jamie\\pycharmprojects\\fastapitest\\venv\\lib\\site-packages\\starlette\\middleware\\exceptions.py\", line 62, in __call__\n    |     await wrap_app_handling_exceptions(self.app, conn)(scope, receive, send)\n    |   File \"c:\\users\\jamie\\pycharmprojects\\fastapitest\\venv\\lib\\site-packages\\starlette\\_exception_handler.py\", line 53, in wrapped_app\n    |     raise exc\n    |   File \"c:\\users\\jamie\\pycharmprojects\\fastapitest\\venv\\lib\\site-packages\\starlette\\_exception_handler.py\", line 42, in wrapped_app\n    |     await app(scope, receive, sender)\n    |   File \"c:\\users\\jamie\\pycharmprojects\\fastapitest\\venv\\lib\\site-packages\\starlette\\routing.py\", line 714, in __call__\n    |     await self.middleware_stack(scope, receive, send)\n    |   File \"c:\\users\\jamie\\pycharmprojects\\fastapitest\\venv\\lib\\site-packages\\starlette\\routing.py\", line 734, in app\n    |     await route.handle(scope, receive, send)\n    |   File \"c:\\users\\jamie\\pycharmprojects\\fastapitest\\venv\\lib\\site-packages\\starlette\\routing.py\", line 288, in handle\n    |     await self.app(scope, receive, send)\n    |   File \"c:\\users\\jamie\\pycharmprojects\\fastapitest\\venv\\lib\\site-packages\\starlette\\routing.py\", line 76, in app\n    |     await wrap_app_handling_exceptions(app, request)(scope, receive, send)\n    |   File \"c:\\users\\jamie\\pycharmprojects\\fastapitest\\venv\\lib\\site-packages\\starlette\\_exception_handler.py\", line 53, in wrapped_app\n    |     raise exc\n    |   File \"c:\\users\\jamie\\pycharmprojects\\fastapitest\\venv\\lib\\site-packages\\starlette\\_exception_handler.py\", line 42, in wrapped_app\n    |     await app(scope, receive, sender)\n    |   File \"c:\\users\\jamie\\pycharmprojects\\fastapitest\\venv\\lib\\site-packages\\starlette\\routing.py\", line 73, in app\n    |     response = await f(request)\n    |   File \"c:\\users\\jamie\\pycharmprojects\\fastapitest\\venv\\lib\\site-packages\\fastapi\\routing.py\", line 301, in app\n    |     raw_response = await run_endpoint_function(\n    |   File \"c:\\users\\jamie\\pycharmprojects\\fastapitest\\venv\\lib\\site-packages\\fastapi\\routing.py\", line 212, in run_endpoint_function\n    |     return await dependant.call(**values)\n    |   File \"C:\\Users\\Jamie\\PycharmProjects\\fastapitest\\main.py\", line 119, in http\n    |     raise ValueError(\"Item not found\")\n    | ValueError: Item not found\n    +------------------------------------\n\nDuring handling of the above exception, another exception occurred:\n\nTraceback (most recent call last):\n  File \"c:\\users\\jamie\\pycharmprojects\\fastapitest\\venv\\lib\\site-packages\\starlette\\middleware\\errors.py\", line 165, in __call__\n    await self.app(scope, receive, _send)\n  File \"c:\\users\\jamie\\pycharmprojects\\fastapitest\\venv\\lib\\site-packages\\starlette\\middleware\\base.py\", line 176, in __call__\n    with recv_stream, send_stream, collapse_excgroups():\n  File \"C:\\Program Files\\Python310\\lib\\contextlib.py\", line 153, in __exit__\n    self.gen.throw(typ, value, traceback)\n  File \"c:\\users\\jamie\\pycharmprojects\\fastapitest\\venv\\lib\\site-packages\\starlette\\_utils.py\", line 82, in collapse_excgroups\n    raise exc\n  File \"c:\\users\\jamie\\pycharmprojects\\fastapitest\\venv\\lib\\site-packages\\starlette\\middleware\\base.py\", line 178, in __call__\n    response = await self.dispatch_func(request, call_next)\n  File \"C:\\Users\\Jamie\\PycharmProjects\\fastapitest\\main.py\", line 30, in dispatch\n    response = await call_next(request)\n  File \"c:\\users\\jamie\\pycharmprojects\\fastapitest\\venv\\lib\\site-packages\\starlette\\middleware\\base.py\", line 156, in call_next\n    raise app_exc\n  File \"c:\\users\\jamie\\pycharmprojects\\fastapitest\\venv\\lib\\site-packages\\starlette\\middleware\\base.py\", line 141, in coro\n    await self.app(scope, receive_or_disconnect, send_no_error)\n  File \"c:\\users\\jamie\\pycharmprojects\\fastapitest\\venv\\lib\\site-packages\\starlette\\middleware\\exceptions.py\", line 62, in __call__\n    await wrap_app_handling_exceptions(self.app, conn)(scope, receive, send)\n  File \"c:\\users\\jamie\\pycharmprojects\\fastapitest\\venv\\lib\\site-packages\\starlette\\_exception_handler.py\", line 53, in wrapped_app\n    raise exc\n  File \"c:\\users\\jamie\\pycharmprojects\\fastapitest\\venv\\lib\\site-packages\\starlette\\_exception_handler.py\", line 42, in wrapped_app\n    await app(scope, receive, sender)\n  File \"c:\\users\\jamie\\pycharmprojects\\fastapitest\\venv\\lib\\site-packages\\starlette\\routing.py\", line 714, in __call__\n    await self.middleware_stack(scope, receive, send)\n  File \"c:\\users\\jamie\\pycharmprojects\\fastapitest\\venv\\lib\\site-packages\\starlette\\routing.py\", line 734, in app\n    await route.handle(scope, receive, send)\n  File \"c:\\users\\jamie\\pycharmprojects\\fastapitest\\venv\\lib\\site-packages\\starlette\\routing.py\", line 288, in handle\n    await self.app(scope, receive, send)\n  File \"c:\\users\\jamie\\pycharmprojects\\fastapitest\\venv\\lib\\site-packages\\starlette\\routing.py\", line 76, in app\n    await wrap_app_handling_exceptions(app, request)(scope, receive, send)\n  File \"c:\\users\\jamie\\pycharmprojects\\fastapitest\\venv\\lib\\site-packages\\starlette\\_exception_handler.py\", line 53, in wrapped_app\n    raise exc\n  File \"c:\\users\\jamie\\pycharmprojects\\fastapitest\\venv\\lib\\site-packages\\starlette\\_exception_handler.py\", line 42, in wrapped_app\n    await app(scope, receive, sender)\n  File \"c:\\users\\jamie\\pycharmprojects\\fastapitest\\venv\\lib\\site-packages\\starlette\\routing.py\", line 73, in app\n    response = await f(request)\n  File \"c:\\users\\jamie\\pycharmprojects\\fastapitest\\venv\\lib\\site-packages\\fastapi\\routing.py\", line 301, in app\n    raw_response = await run_endpoint_function(\n  File \"c:\\users\\jamie\\pycharmprojects\\fastapitest\\venv\\lib\\site-packages\\fastapi\\routing.py\", line 212, in run_endpoint_function\n    return await dependant.call(**values)\n  File \"C:\\Users\\Jamie\\PycharmProjects\\fastapitest\\main.py\", line 119, in http\n    raise ValueError(\"Item not found\")\nValueError: Item not found\n", "logger": "error_logger"}
{"timestamp": "2025-05-08T18:05:53.872130+00:00", "level": "ERROR", "correlation_id": "58c9b403-6610-48f5-830b-72300cac0dc8", "response_time": 0.00499725341796875, "error": "Value is wrong", "message": "Unhandled Exception", "stack_trace": "  + Exception Group Traceback (most recent call last):\n  |   File \"c:\\users\\jamie\\pycharmprojects\\fastapitest\\venv\\lib\\site-packages\\starlette\\_utils.py\", line 76, in collapse_excgroups\n  |     yield\n  |   File \"c:\\users\\jamie\\pycharmprojects\\fastapitest\\venv\\lib\\site-packages\\starlette\\middleware\\base.py\", line 177, in __call__\n  |     async with anyio.create_task_group() as task_group:\n  |   File \"c:\\users\\jamie\\pycharmprojects\\fastapitest\\venv\\lib\\site-packages\\anyio\\_backends\\_asyncio.py\", line 772, in __aexit__\n  |     raise BaseExceptionGroup(\n  | exceptiongroup.ExceptionGroup: unhandled errors in a TaskGroup (1 sub-exception)\n  +-+---------------- 1 ----------------\n    | Traceback (most recent call last):\n    |   File \"c:\\users\\jamie\\pycharmprojects\\fastapitest\\venv\\lib\\site-packages\\starlette\\middleware\\errors.py\", line 165, in __call__\n    |     await self.app(scope, receive, _send)\n    |   File \"c:\\users\\jamie\\pycharmprojects\\fastapitest\\venv\\lib\\site-packages\\starlette\\middleware\\base.py\", line 176, in __call__\n    |     with recv_stream, send_stream, collapse_excgroups():\n    |   File \"C:\\Program Files\\Python310\\lib\\contextlib.py\", line 153, in __exit__\n    |     self.gen.throw(typ, value, traceback)\n    |   File \"c:\\users\\jamie\\pycharmprojects\\fastapitest\\venv\\lib\\site-packages\\starlette\\_utils.py\", line 82, in collapse_excgroups\n    |     raise exc\n    |   File \"c:\\users\\jamie\\pycharmprojects\\fastapitest\\venv\\lib\\site-packages\\starlette\\middleware\\base.py\", line 178, in __call__\n    |     response = await self.dispatch_func(request, call_next)\n    |   File \"C:\\Users\\Jamie\\PycharmProjects\\fastapitest\\main.py\", line 30, in dispatch\n    |     response = await call_next(request)\n    |   File \"c:\\users\\jamie\\pycharmprojects\\fastapitest\\venv\\lib\\site-packages\\starlette\\middleware\\base.py\", line 156, in call_next\n    |     raise app_exc\n    |   File \"c:\\users\\jamie\\pycharmprojects\\fastapitest\\venv\\lib\\site-packages\\starlette\\middleware\\base.py\", line 141, in coro\n    |     await self.app(scope, receive_or_disconnect, send_no_error)\n    |   File \"c:\\users\\jamie\\pycharmprojects\\fastapitest\\venv\\lib\\site-packages\\starlette\\middleware\\exceptions.py\", line 62, in __call__\n    |     await wrap_app_handling_exceptions(self.app, conn)(scope, receive, send)\n    |   File \"c:\\users\\jamie\\pycharmprojects\\fastapitest\\venv\\lib\\site-packages\\starlette\\_exception_handler.py\", line 53, in wrapped_app\n    |     raise exc\n    |   File \"c:\\users\\jamie\\pycharmprojects\\fastapitest\\venv\\lib\\site-packages\\starlette\\_exception_handler.py\", line 42, in wrapped_app\n    |     await app(scope, receive, sender)\n    |   File \"c:\\users\\jamie\\pycharmprojects\\fastapitest\\venv\\lib\\site-packages\\starlette\\routing.py\", line 714, in __call__\n    |     await self.middleware_stack(scope, receive, send)\n    |   File \"c:\\users\\jamie\\pycharmprojects\\fastapitest\\venv\\lib\\site-packages\\starlette\\routing.py\", line 734, in app\n    |     await route.handle(scope, receive, send)\n    |   File \"c:\\users\\jamie\\pycharmprojects\\fastapitest\\venv\\lib\\site-packages\\starlette\\routing.py\", line 288, in handle\n    |     await self.app(scope, receive, send)\n    |   File \"c:\\users\\jamie\\pycharmprojects\\fastapitest\\venv\\lib\\site-packages\\starlette\\routing.py\", line 76, in app\n    |     await wrap_app_handling_exceptions(app, request)(scope, receive, send)\n    |   File \"c:\\users\\jamie\\pycharmprojects\\fastapitest\\venv\\lib\\site-packages\\starlette\\_exception_handler.py\", line 53, in wrapped_app\n    |     raise exc\n    |   File \"c:\\users\\jamie\\pycharmprojects\\fastapitest\\venv\\lib\\site-packages\\starlette\\_exception_handler.py\", line 42, in wrapped_app\n    |     await app(scope, receive, sender)\n    |   File \"c:\\users\\jamie\\pycharmprojects\\fastapitest\\venv\\lib\\site-packages\\starlette\\routing.py\", line 73, in app\n    |     response = await f(request)\n    |   File \"c:\\users\\jamie\\pycharmprojects\\fastapitest\\venv\\lib\\site-packages\\fastapi\\routing.py\", line 301, in app\n    |     raw_response = await run_endpoint_function(\n    |   File \"c:\\users\\jamie\\pycharmprojects\\fastapitest\\venv\\lib\\site-packages\\fastapi\\routing.py\", line 212, in run_endpoint_function\n    |     return await dependant.call(**values)\n    |   File \"C:\\Users\\Jamie\\PycharmProjects\\fastapitest\\main.py\", line 119, in http\n    |     raise ValueError(\"Value is wrong\")\n    | ValueError: Value is wrong\n    +------------------------------------\n\nDuring handling of the above exception, another exception occurred:\n\nTraceback (most recent call last):\n  File \"c:\\users\\jamie\\pycharmprojects\\fastapitest\\venv\\lib\\site-packages\\starlette\\middleware\\errors.py\", line 165, in __call__\n    await self.app(scope, receive, _send)\n  File \"c:\\users\\jamie\\pycharmprojects\\fastapitest\\venv\\lib\\site-packages\\starlette\\middleware\\base.py\", line 176, in __call__\n    with recv_stream, send_stream, collapse_excgroups():\n  File \"C:\\Program Files\\Python310\\lib\\contextlib.py\", line 153, in __exit__\n    self.gen.throw(typ, value, traceback)\n  File \"c:\\users\\jamie\\pycharmprojects\\fastapitest\\venv\\lib\\site-packages\\starlette\\_utils.py\", line 82, in collapse_excgroups\n    raise exc\n  File \"c:\\users\\jamie\\pycharmprojects\\fastapitest\\venv\\lib\\site-packages\\starlette\\middleware\\base.py\", line 178, in __call__\n    response = await self.dispatch_func(request, call_next)\n  File \"C:\\Users\\Jamie\\PycharmProjects\\fastapitest\\main.py\", line 30, in dispatch\n    response = await call_next(request)\n  File \"c:\\users\\jamie\\pycharmprojects\\fastapitest\\venv\\lib\\site-packages\\starlette\\middleware\\base.py\", line 156, in call_next\n    raise app_exc\n  File \"c:\\users\\jamie\\pycharmprojects\\fastapitest\\venv\\lib\\site-packages\\starlette\\middleware\\base.py\", line 141, in coro\n    await self.app(scope, receive_or_disconnect, send_no_error)\n  File \"c:\\users\\jamie\\pycharmprojects\\fastapitest\\venv\\lib\\site-packages\\starlette\\middleware\\exceptions.py\", line 62, in __call__\n    await wrap_app_handling_exceptions(self.app, conn)(scope, receive, send)\n  File \"c:\\users\\jamie\\pycharmprojects\\fastapitest\\venv\\lib\\site-packages\\starlette\\_exception_handler.py\", line 53, in wrapped_app\n    raise exc\n  File \"c:\\users\\jamie\\pycharmprojects\\fastapitest\\venv\\lib\\site-packages\\starlette\\_exception_handler.py\", line 42, in wrapped_app\n    await app(scope, receive, sender)\n  File \"c:\\users\\jamie\\pycharmprojects\\fastapitest\\venv\\lib\\site-packages\\starlette\\routing.py\", line 714, in __call__\n    await self.middleware_stack(scope, receive, send)\n  File \"c:\\users\\jamie\\pycharmprojects\\fastapitest\\venv\\lib\\site-packages\\starlette\\routing.py\", line 734, in app\n    await route.handle(scope, receive, send)\n  File \"c:\\users\\jamie\\pycharmprojects\\fastapitest\\venv\\lib\\site-packages\\starlette\\routing.py\", line 288, in handle\n    await self.app(scope, receive, send)\n  File \"c:\\users\\jamie\\pycharmprojects\\fastapitest\\venv\\lib\\site-packages\\starlette\\routing.py\", line 76, in app\n    await wrap_app_handling_exceptions(app, request)(scope, receive, send)\n  File \"c:\\users\\jamie\\pycharmprojects\\fastapitest\\venv\\lib\\site-packages\\starlette\\_exception_handler.py\", line 53, in wrapped_app\n    raise exc\n  File \"c:\\users\\jamie\\pycharmprojects\\fastapitest\\venv\\lib\\site-packages\\starlette\\_exception_handler.py\", line 42, in wrapped_app\n    await app(scope, receive, sender)\n  File \"c:\\users\\jamie\\pycharmprojects\\fastapitest\\venv\\lib\\site-packages\\starlette\\routing.py\", line 73, in app\n    response = await f(request)\n  File \"c:\\users\\jamie\\pycharmprojects\\fastapitest\\venv\\lib\\site-packages\\fastapi\\routing.py\", line 301, in app\n    raw_response = await run_endpoint_function(\n  File \"c:\\users\\jamie\\pycharmprojects\\fastapitest\\venv\\lib\\site-packages\\fastapi\\routing.py\", line 212, in run_endpoint_function\n    return await dependant.call(**values)\n  File \"C:\\Users\\Jamie\\PycharmProjects\\fastapitest\\main.py\", line 119, in http\n    raise ValueError(\"Value is wrong\")\nValueError: Value is wrong\n", "logger": "error_logger"}
